<robot name="onshape">
<link name="torso">
<visual>
<origin xyz="0 0 0" rpy="0 -0 0" />
<geometry>
<mesh filename="package://cal_hum_description/meshs/torso.stl"/>
</geometry>
<material name="torso_material">
<color rgba="0.91764705882352937127 0.91764705882352937127 0.91764705882352937127 1.0"/>
</material>
</visual>
<!-- Shapes for torso -->
<inertial>
<origin xyz="-0.004727739999999995904 -0.00014552999999999997036 0.10283863000000012522" rpy="0 0 0"/>
<mass value="2.927037159999976268" />
<inertia ixx="0.051421070231833232445" ixy="-0.00058153531110748330271"  ixz="-0.0015361604440174395254" iyy="0.03740969429092060039" iyz="0.00070497665986464313169" izz="0.028925496243936709567" />
</inertial>
</link>

<link name="ll_hr">
<visual>
<origin xyz="7.3495744739961654391e-17 -0.069999999999999895639 1.4216918258373129891e-16" rpy="-9.4325484228159805336e-28 -0.78539816339744794593 5.7851457597003556322e-46" />
<geometry>
<mesh filename="package://cal_hum_description/meshs/ll_hr.stl"/>
</geometry>
<material name="ll_hr_material">
<color rgba="0.91764705882352937127 0.91764705882352937127 0.91764705882352937127 1.0"/>
</material>
</visual>
<!-- Shapes for ll_hr -->
<inertial>
<origin xyz="-0.0062338958093474212616 0.00070432000000006367551 -0.037208835638444626159" rpy="0 0 0"/>
<mass value="0.73133287000000013478" />
<inertia ixx="0.0016295722474070192722" ixy="-3.587491485631832841e-05"  ixz="-8.2585115000000363381e-05" iyy="0.0015558630100000001711" iyz="6.2591175029895166916e-06" izz="0.00073101174259298054049" />
</inertial>
</link>

<link name="ll_haa">
<visual>
<origin xyz="0.064999999999998128719 -0.069999999999998424594 0.015799999999996167804" rpy="-1.8385391135088681522e-15 0.78539816339744872309 1.8119264448143602674e-31" />
<geometry>
<mesh filename="package://cal_hum_description/meshs/ll_haa.stl"/>
</geometry>
<material name="ll_haa_material">
<color rgba="0.91764705882352937127 0.91764705882352937127 0.91764705882352937127 1.0"/>
</material>
</visual>
<!-- Shapes for ll_haa -->
<inertial>
<origin xyz="0.0016821232786486395305 -0.014174999999998575892 -0.03807941540607523434" rpy="0 0 0"/>
<mass value="0.79600000000000059597" />
<inertia ixx="0.0013606266472201602579" ixy="5.2319821399484098265e-06"  ixz="-2.4349982350893521863e-05" iyy="0.0017341651457972642042" iyz="-4.6775551431596225187e-05" izz="0.00080476822545456363177" />
</inertial>
</link>

<link name="ll_hfe">
<visual>
<origin xyz="0.10309616869699694819 -0.011172287142744870975 -0.085799999999993839528" rpy="1.5707963267948887864 -6.0836744561200820005e-15 1.570796326794896558" />
<geometry>
<mesh filename="package://cal_hum_description/meshs/ll_hfe.stl"/>
</geometry>
<material name="ll_hfe_material">
<color rgba="0.91764705882352937127 0.91764705882352937127 0.91764705882352937127 1.0"/>
</material>
</visual>
<!-- Shapes for ll_hfe -->
<inertial>
<origin xyz="-0.033668701303003839564 0.018560382857254538458 0.0094327400000052789852" rpy="0 0 0"/>
<mass value="3.5233394799999966374" />
<inertia ixx="0.014723867807757555146" ixy="-0.0011043766273472579217"  ixz="0.0050843212469392539202" iyy="0.031285359683627861349" iyz="0.0025289857534554773498" izz="0.02764146804704123439" />
</inertial>
</link>

<link name="ll_kfe">
<visual>
<origin xyz="0.3230961686969971991 -0.011172287142754453587 -0.15999999999999381384" rpy="1.5707963267948887864 -6.0836744561191101239e-15 1.570796326794896558" />
<geometry>
<mesh filename="package://cal_hum_description/meshs/ll_kfe.stl"/>
</geometry>
<material name="ll_kfe_material">
<color rgba="0.91764705882352937127 0.91764705882352937127 0.91764705882352937127 1.0"/>
</material>
</visual>
<!-- Shapes for ll_kfe -->
<inertial>
<origin xyz="-0.031901741303003716688 0.091689672857244886028 -0.0536054399999959727" rpy="0 0 0"/>
<mass value="0.24071601000000006354" />
<inertia ixx="0.0028203399079755608891" ixy="-0.0010287616507221770956"  ixz="0.00054797909062976723343" iyy="0.0021837337502509314609" iyz="0.0011903958858475701191" izz="0.0035876999592870844127" />
</inertial>
</link>

<link name="ll_ffe">
<visual>
<origin xyz="0.50309616869699935737 -0.011172287142762124534 -0.15999999999998928968" rpy="1.5707963267948887864 -6.0836744561191101239e-15 1.570796326794896558" />
<geometry>
<mesh filename="package://cal_hum_description/meshs/ll_ffe.stl"/>
</geometry>
<material name="ll_ffe_material">
<color rgba="0.91764705882352937127 0.91764705882352937127 0.91764705882352937127 1.0"/>
</material>
</visual>
<!-- Shapes for ll_ffe -->
<inertial>
<origin xyz="0.055405788696998858889 0.063313802857237297395 -0.069452679999992356086" rpy="0 0 0"/>
<mass value="0.099322750000000056825" />
<inertia ixx="0.00088993358176636466143" ixy="-0.00036825176555067606942"  ixz="0.00040621351190161229415" iyy="0.00083481807900864497905" iyz="0.00042897209409484580523" izz="0.00075505166816962972394" />
</inertial>
</link>

<link name="ll_faa">
<visual>
<origin xyz="-0.15999999999999109379 0.50309616869699724795 -0.031172287142789679298" rpy="-1.570796326794896558 -1.570796326794896558 0" />
<geometry>
<mesh filename="package://cal_hum_description/meshs/ll_faa.stl"/>
</geometry>
<material name="ll_faa_material">
<color rgba="0.91764705882352937127 0.91764705882352937127 0.91764705882352937127 1.0"/>
</material>
</visual>
<!-- Shapes for ll_faa -->
<collision>
<origin xyz="8.9095397726168812369e-15 -0.0049038313030027591566 0.019827712857210317426" rpy="-1.570796326794896558 -1.570796326794896558 0" />
<geometry>
<box size="0.14000000000000001332 0.055000000000000000278 0.055000000000000000278" />
</geometry>
</collision>
<inertial>
<origin xyz="-0.069331049999991151145 0.052652478696997517815 0.052034212857210271341" rpy="0 0 0"/>
<mass value="0.19869955000000011358" />
<inertia ixx="0.001573779576400361228" ixy="0.00099441722230272379911"  ixz="0.00051970219197393363597" iyy="0.0014921720313034881732" iyz="-0.00053920924933122604209" izz="0.0020995076431026059131" />
</inertial>
</link>

<link name="LL_FOOT">
<inertial>
<origin xyz="0 0 0" rpy="0 0 0" />
<mass value="1e-9" />
<inertia ixx="0" ixy="0" ixz="0" iyy="0" iyz="0" izz="0" />
</inertial>
</link>
<joint name="LL_FOOT_frame" type="fixed">
<origin xyz="1.360023205165816762e-15 -0.033000000000000473399 0.020976404179762330598" rpy="-1.5707963267948936714 -1.570796326794896558 0" />
<parent link="ll_faa" />
<child link="LL_FOOT" />
<axis xyz="0 0 0"/>
</joint>

<joint name="LL_FAA" type="revolute">
<origin xyz="6.6613381477509392425e-16 0.020000000000026579849 -1.9428902930940239457e-15" rpy="-1.5707963267948634734 -1.5707963267948870101 0" />
<parent link="ll_ffe" />
<child link="ll_faa" />
<axis xyz="0 0 1"/>
<limit effort="18" velocity="42" lower="-0.52359877559829881566" upper="0.52359877559829881566"/>
<joint_properties friction="0.0"/>
</joint>

<joint name="LL_FFE" type="revolute">
<origin xyz="-0.18000000000000204725 7.6709472107694409715e-15 -4.5519144009631418157e-15" rpy="-4.142519660632226433e-15 -2.2343238370579094176e-15 5.9396931817444589069e-15" />
<parent link="ll_kfe" />
<child link="ll_ffe" />
<axis xyz="0 0 1"/>
<limit effort="60" velocity="20" lower="-0.52359877559829881566" upper="1.2217304763960306069"/>
<joint_properties friction="0.0"/>
</joint>

<joint name="LL_KFE" type="revolute">
<origin xyz="-0.2200000000000001954 9.5826124812958823895e-15 0.074199999999999946554" rpy="2.3904489498968254871e-15 1.85268467234245216e-15 -1.2267964422107583764e-14" />
<parent link="ll_hfe" />
<child link="ll_kfe" />
<axis xyz="0 0 1"/>
<limit effort="120" velocity="14" lower="0" upper="2.0943951023931952626"/>
<joint_properties friction="0.0"/>
</joint>

<joint name="LL_HFE" type="revolute">
<origin xyz="-1.3322676295501878485e-15 0.015799999999994734923 -0.065000000000000376921" rpy="-1.57079632679489678 -0.78539816339744150664 -8.5144621655032178393e-15" />
<parent link="ll_haa" />
<child link="ll_hfe" />
<axis xyz="0 0 1"/>
<limit effort="90" velocity="20" lower="-1.9198621771937625091" upper="1.9198621771937625091"/>
<joint_properties friction="0.0"/>
</joint>

<joint name="LL_HAA" type="revolute">
<origin xyz="0.015799999999996153927 -1.360023205165816762e-15 -0.064999999999997906674" rpy="1.2864546617328002073e-15 -1.5707963267948952257 0" />
<parent link="ll_hr" />
<child link="ll_haa" />
<axis xyz="0 0 1"/>
<limit effort="60" velocity="23" lower="-0.52359877559829881566" upper="0.785398163397448279"/>
<joint_properties friction="0.0"/>
</joint>

<joint name="LL_HR" type="revolute">
<origin xyz="-1.5163483659484564161e-16 0.069999999999999895639 -4.8559453586656402725e-17" rpy="1.3339637907287298868e-27 0.78539816339744794593 1.2332799712965867172e-17" />
<parent link="torso" />
<child link="ll_hr" />
<axis xyz="0 0 1"/>
<limit effort="60" velocity="23" lower="-0.52359877559829881566" upper="1.0471975511965976313"/>
<joint_properties friction="0.0"/>
</joint>

<link name="lr_hr">
<visual>
<origin xyz="8.2629660217742679531e-17 0.070000000000000103806 1.6717631263260787336e-16" rpy="-1.8089567794274052882e-27 -0.78539816339744805695 -2.5195485606773874785e-32" />
<geometry>
<mesh filename="package://cal_hum_description/meshs/lr_hr.stl"/>
</geometry>
<material name="lr_hr_material">
<color rgba="0.91764705882352937127 0.91764705882352937127 0.91764705882352937127 1.0"/>
</material>
</visual>
<!-- Shapes for lr_hr -->
<inertial>
<origin xyz="-0.0062727442559057612279 -7.2999999999781572946e-05 -0.037208665932817117095" rpy="0 0 0"/>
<mass value="0.73133287000000080091" />
<inertia ixx="0.001576750489808424532" ixy="2.9236526815963499884e-06"  ixz="-7.7950030122177265063e-05" iyy="0.001187213522323545857" iyz="5.8143685298790408951e-06" izz="0.00067293016361788277491" />
</inertial>
</link>

<link name="lr_haa">
<visual>
<origin xyz="0.064999999999999238942 0.070000000000000214828 0.01579999999999669863" rpy="4.1611137104217372739e-15 0.78539816339744750184 -2.609581273203703118e-32" />
<geometry>
<mesh filename="package://cal_hum_description/meshs/lr_haa.stl"/>
</geometry>
<material name="lr_haa_material">
<color rgba="0.91764705882352937127 0.91764705882352937127 0.91764705882352937127 1.0"/>
</material>
</visual>
<!-- Shapes for lr_haa -->
<inertial>
<origin xyz="-0.00068406107216703593288 0.0075435900000006706617 -0.039387584164473465886" rpy="0 0 0"/>
<mass value="0.79599999999999970779" />
<inertia ixx="0.0013145690070147919831" ixy="1.2277307941681106467e-06"  ixz="1.0572493149092934362e-06" iyy="0.0017084353807578767353" iyz="0.00011067577011200066582" izz="0.00078005700465820710428" />
</inertial>
</link>

<link name="lr_hfe">
<visual>
<origin xyz="0.1030961686969951302 -0.011172287142737326662 0.085800000000000556377" rpy="1.5707963267948961139 -2.85792382801746712e-16 1.570796326794896558" />
<geometry>
<mesh filename="package://cal_hum_description/meshs/lr_hfe.stl"/>
</geometry>
<material name="lr_hfe_material">
<color rgba="0.91764705882352937127 0.91764705882352937127 0.91764705882352937127 1.0"/>
</material>
</visual>
<!-- Shapes for lr_hfe -->
<inertial>
<origin xyz="-0.053342251303004593888 0.00067071285726267096394 -0.04024899999999909106" rpy="0 0 0"/>
<mass value="2.4960000000000079901" />
<inertia ixx="0.0057303405152839713074" ixy="0.00018071400178366810738"  ixz="-0.0014540430701991114131" iyy="0.017093925036772674581" iyz="2.7180240668988058813e-05" izz="0.01760045747628725607" />
</inertial>
</link>

<link name="lr_kfe">
<visual>
<origin xyz="0.32309616869699459007 -0.011172287142742421545 0.16000000000000014211" rpy="1.570796326794896558 3.851859889559417799e-33 1.570796326794896558" />
<geometry>
<mesh filename="package://cal_hum_description/meshs/lr_kfe.stl"/>
</geometry>
<material name="lr_kfe_material">
<color rgba="0.91764705882352937127 0.91764705882352937127 0.91764705882352937127 1.0"/>
</material>
</visual>
<!-- Shapes for lr_kfe -->
<inertial>
<origin xyz="-0.073422831303005475778 -0.0013121671427424198147 0.00043914000000000452673" rpy="0 0 0"/>
<mass value="0.24099999999999996425" />
<inertia ixx="5.8566224651896831553e-05" ixy="-6.866714987173241371e-05"  ixz="1.0787864326451399589e-06" iyy="0.0010619126261204787399" iyz="-2.5038354916523903425e-07" izz="0.0010651730211027989666" />
</inertial>
</link>

<link name="lr_ffe">
<visual>
<origin xyz="0.50309616869699469444 -0.011172287142742098887 0.16000000000000003109" rpy="1.570796326794896558 -2.0533627650334198489e-32 1.570796326794896558" />
<geometry>
<mesh filename="package://cal_hum_description/meshs/lr_ffe.stl"/>
</geometry>
<material name="lr_ffe_material">
<color rgba="0.91764705882352937127 0.91764705882352937127 0.91764705882352937127 1.0"/>
</material>
</visual>
<!-- Shapes for lr_ffe -->
<inertial>
<origin xyz="-0.0010781713030053596825 0.02377071285725790642 -6.7999999999984739318e-05" rpy="0 0 0"/>
<mass value="0.099322280000000012778" />
<inertia ixx="7.6973158492800531683e-05" ixy="-1.23021144265398259e-05"  ixz="-2.794156637572368013e-07" iyy="1.1391027650605378688e-05" iyz="-9.2660656262807517484e-07" izz="8.254687702691370396e-05" />
</inertial>
</link>

<link name="lr_faa">
<visual>
<origin xyz="0.16000000000000119682 0.50309616869699469444 -0.031172287142753371536" rpy="-1.570796326794896558 -1.570796326794896558 0" />
<geometry>
<mesh filename="package://cal_hum_description/meshs/lr_faa.stl"/>
</geometry>
<material name="lr_faa_material">
<color rgba="0.91764705882352937127 0.91764705882352937127 0.91764705882352937127 1.0"/>
</material>
</visual>
<!-- Shapes for lr_faa -->
<collision>
<origin xyz="1.193489751472043281e-15 -0.0049038313030053126695 0.019827712857246625189" rpy="-1.570796326794896558 -1.570796326794896558 0" />
<geometry>
<box size="0.14000000000000001332 0.055000000000000000278 0.055000000000000000278" />
</geometry>
</collision>
<inertial>
<origin xyz="7.8300000001224612234e-05 -0.0037475313030054246966 0.012491522857246632749" rpy="0 0 0"/>
<mass value="0.19869955000000000256" />
<inertia ixx="0.00030590484912064767279" ixy="-2.2494771641131489699e-07"  ixz="1.4827443740914956909e-07" iyy="0.00025477811414993862572" iyz="7.6884878815159113933e-06" izz="0.0001585121051303447538" />
</inertial>
</link>

<link name="LR_FOOT">
<inertial>
<origin xyz="0 0 0" rpy="0 0 0" />
<mass value="1e-9" />
<inertia ixx="0" ixy="0" ixz="0" iyy="0" iyz="0" izz="0" />
</inertial>
</link>
<joint name="LR_FOOT_frame" type="fixed">
<origin xyz="-7.4940054162198066479e-16 -0.032999999999999585221 0.020976404179758215834" rpy="-1.570796326794896558 -1.570796326794896558 0" />
<parent link="lr_faa" />
<child link="LR_FOOT" />
<axis xyz="0 0 0"/>
</joint>

<joint name="LR_FAA" type="revolute">
<origin xyz="0 0.020000000000011272649 -1.1379786002407854539e-15" rpy="-1.5707963267948958919 -1.570796326794896336 0" />
<parent link="lr_ffe" />
<child link="lr_faa" />
<axis xyz="0 0 1"/>
<limit effort="18" velocity="42" lower="-0.52359877559829881566" upper="0.52359877559829881566"/>
<joint_properties friction="0.0"/>
</joint>

<joint name="LR_FFE" type="revolute">
<origin xyz="-0.18000000000000010436 -3.2265856653168611956e-16 1.3877787807814456755e-16" rpy="4.6473388338391139794e-16 1.3322676295501568857e-15 -1.0785973072212841079e-15" />
<parent link="lr_kfe" />
<child link="lr_ffe" />
<axis xyz="0 0 1"/>
<limit effort="60" velocity="23" lower="-0.52359877559829881566" upper="1.2217304763960306069"/>
<joint_properties friction="0.0"/>
</joint>

<joint name="LR_KFE" type="revolute">
<origin xyz="-0.22000000000000236033 5.4522358849951046977e-15 -0.074200000000000695954" rpy="-6.6483608203348963737e-16 -1.5373536224247637345e-15 -8.6042284408420128485e-16" />
<parent link="lr_hfe" />
<child link="lr_kfe" />
<axis xyz="0 0 1"/>
<limit effort="120" velocity="14" lower="0" upper="2.0943951023931952626"/>
<joint_properties friction="0.0"/>
</joint>

<joint name="LR_HFE" type="revolute">
<origin xyz="-6.5503158452884235885e-15 -0.015800000000000355427 -0.064999999999994145794" rpy="-1.570796326794891673 -0.78539816339743961926 -6.3317480822993795962e-15" />
<parent link="lr_haa" />
<child link="lr_hfe" />
<axis xyz="0 0 1"/>
<limit effort="90" velocity="20" lower="-1.9198621771937625091" upper="1.9198621771937625091"/>
<joint_properties friction="0.0"/>
</joint>

<joint name="LR_HAA" type="revolute">
<origin xyz="0.015799999999996230254 1.3461454173580023053e-15 -0.064999999999997726263" rpy="-2.5294501794417421484e-15 -1.5707963267948930053 0" />
<parent link="lr_hr" />
<child link="lr_haa" />
<axis xyz="0 0 1"/>
<limit effort="60" velocity="23" lower="-1.0471975511965976313" upper="0.52359877559829881566"/>
<joint_properties friction="0.0"/>
</joint>

<joint name="LR_HR" type="revolute">
<origin xyz="-1.7663949738338549142e-16 -0.070000000000000103806 -5.9783511249299827774e-17" rpy="-4.767057147862150383e-16 0.78539816339744816798 -6.741636871132349286e-16" />
<parent link="torso" />
<child link="lr_hr" />
<axis xyz="0 0 1"/>
<limit effort="60" velocity="23" lower="-1.0471975511965976313" upper="0.52359877559829881566"/>
<joint_properties friction="0.0"/>
</joint>


</robot>
