<robot name="onshape">
<link name="torso">
<visual>
<origin xyz="0 0 0" rpy="0 -0 0" />
<geometry>
<mesh filename="package://cal_hum_description/meshs/torso.stl"/>
</geometry>
<material name="torso_material">
<color rgba="0.91764705882352937127 0.91764705882352937127 0.91764705882352937127 1.0"/>
</material>
</visual>
<!-- Shapes for torso -->
<collision>
<origin xyz="0.020000000000000000416 0 0.11999999999999999556" rpy="0 -0 0" />
<geometry>
<box size="0.17999999999999999334 0.25 0.25" />
</geometry>
</collision>
<inertial>
<origin xyz="0.012329400000000030266 -0.0023557000000000070071 0.11404699999999995397" rpy="0 0 0"/>
<mass value="5.3781180999999893544" />
<inertia ixx="0.10633935724772884679" ixy="-0.0011518417369268834673"  ixz="-0.0019798987901618425415" iyy="0.077153530025598202058" iyz="0.00063966268739628902133" izz="0.049558109407867527441" />
</inertial>
</link>

<link name="ll_hr">
<visual>
<origin xyz="8.3411161867551658023e-17 -0.069999999999999854006 1.5210270693501451838e-16" rpy="-4.7915784122997851406e-28 -0.78539816339744950024 1.3452465257518275743e-43" />
<geometry>
<mesh filename="package://cal_hum_description/meshs/ll_hr.stl"/>
</geometry>
<material name="ll_hr_material">
<color rgba="0.91764705882352937127 0.91764705882352937127 0.91764705882352937127 1.0"/>
</material>
</visual>
<!-- Shapes for ll_hr -->
<inertial>
<origin xyz="-0.0054878557287887140895 0.00067000000000172477144 -0.060008616985397597587" rpy="0 0 0"/>
<mass value="0.75099999999998279243" />
<inertia ixx="0.0015411853856991117925" ixy="3.4458003201060548787e-06"  ixz="-9.5391365132054307149e-05" iyy="0.0011651757733619697976" iyz="5.6603649620037817944e-06" izz="0.00073765772259487029372" />
</inertial>
</link>

<link name="ll_haa">
<visual>
<origin xyz="0.064999999999999572009 -0.069999999999999770739 0.015799999999995966576" rpy="4.2166986512874552266e-15 0.785398163397448279 0" />
<geometry>
<mesh filename="package://cal_hum_description/meshs/ll_haa.stl"/>
</geometry>
<material name="ll_haa_material">
<color rgba="0.91764705882352937127 0.91764705882352937127 0.91764705882352937127 1.0"/>
</material>
</visual>
<!-- Shapes for ll_haa -->
<inertial>
<origin xyz="0.00063772656283812845235 -0.0081199999999998599687 -0.060865931429811212516" rpy="0 0 0"/>
<mass value="0.85100000000001085887" />
<inertia ixx="0.0013734389493930446949" ixy="-1.9074937059428987427e-06"  ixz="4.7795124019210976426e-06" iyy="0.0017643939390453056582" iyz="-0.00013437288005948761264" izz="0.00089199996414278967614" />
</inertial>
</link>

<link name="ll_hfe">
<visual>
<origin xyz="0.10309616869699469999 -0.011172287142745998545 -0.085799999999994921995" rpy="1.5707963267949038855 1.7489923064381119945e-14 1.570796326794896558" />
<geometry>
<mesh filename="package://cal_hum_description/meshs/ll_hfe.stl"/>
</geometry>
<material name="ll_hfe_material">
<color rgba="0.91764705882352937127 0.91764705882352937127 0.91764705882352937127 1.0"/>
</material>
</visual>
<!-- Shapes for ll_hfe -->
<collision>
<origin xyz="9.6168696995704849861e-05 -2.8714274354774138587e-07 0.054200000000005674194" rpy="-3.1415926535897860106 1.7489923064381119945e-14 1.570796326794896558" />
<geometry>
<cylinder length="0.089999999999999996669" radius="0.061499999999999999112" />
</geometry>
</collision>
<collision>
<origin xyz="-0.11490383130300427239 -2.8714274346100521207e-07 0.059200000000006455791" rpy="-3.1415926535897860106 1.7489923064381119945e-14 1.570796326794896558" />
<geometry>
<cylinder length="0.080000000000000001665" radius="0.051999999999999997613" />
</geometry>
</collision>
<inertial>
<origin xyz="-0.054802291303004374567 -0.00042046714274374119569 0.043015600000006079529" rpy="0 0 0"/>
<mass value="2.2535340100000000874" />
<inertia ixx="0.0050853613820006316956" ixy="0.00017735960141768714331"  ixz="0.0012738415098089515137" iyy="0.015264146154526630345" iyz="-4.5383172503089316407e-05" izz="0.01585741252279511404" />
</inertial>
</link>

<link name="ll_kfe">
<visual>
<origin xyz="0.3230961686969961999 -0.011172287143240726068 -0.15999999999999259259" rpy="1.5707963267948958919 -1.8203544808569294933e-14 1.570796326794896558" />
<geometry>
<mesh filename="package://cal_hum_description/meshs/ll_kfe.stl"/>
</geometry>
<material name="ll_kfe_material">
<color rgba="0.91764705882352937127 0.91764705882352937127 0.91764705882352937127 1.0"/>
</material>
</visual>
<!-- Shapes for ll_kfe -->
<collision>
<origin xyz="-0.056903831303003915565 -0.0011722871432436384603 7.2997163869104042533e-15" rpy="1.5707963267948958919 -1.8203544808569294933e-14 1.570796326794896558" />
<geometry>
<box size="0.02999999999999999889 0.040000000000000000833 0.16000000000000000333" />
</geometry>
</collision>
<inertial>
<origin xyz="-0.073422831303003699421 -0.0013121671432436352034 -0.00043913999999279474491" rpy="0 0 0"/>
<mass value="0.24071601000000064641" />
<inertia ixx="5.8497212291950341544e-05" ixy="-6.8586225347447676002e-05"  ixz="-1.0773459750966386834e-06" iyy="0.0010606612937310410782" iyz="2.500965311704115002e-07" izz="0.0010639178434183461756" />
</inertial>
</link>

<link name="ll_ffe">
<visual>
<origin xyz="0.50309616869699835817 -0.011172287143647298413 -0.15999999999998817946" rpy="1.5707963267948958919 -1.8203544808569294933e-14 1.570796326794896558" />
<geometry>
<mesh filename="package://cal_hum_description/meshs/ll_ffe.stl"/>
</geometry>
<material name="ll_ffe_material">
<color rgba="0.91764705882352937127 0.91764705882352937127 0.91764705882352937127 1.0"/>
</material>
</visual>
<!-- Shapes for ll_ffe -->
<inertial>
<origin xyz="-0.0010781713030016959465 0.023770712856349782149 6.8000000012059254968e-05" rpy="0 0 0"/>
<mass value="0.099322750000000056825" />
<inertia ixx="7.6973129115221494722e-05" ixy="-1.2302395988726537004e-05"  ixz="2.7947672524258101482e-07" iyy="1.1391165311710985418e-05" iyz="9.2670402410296198204e-07" izz="8.2547053941301682658e-05" />
</inertial>
</link>

<link name="ll_faa">
<visual>
<origin xyz="-0.15999999999998909539 0.50309616869699735897 -0.031172287143649141106" rpy="-1.570796326794896558 -1.570796326794896558 0" />
<geometry>
<mesh filename="package://cal_hum_description/meshs/ll_faa.stl"/>
</geometry>
<material name="ll_faa_material">
<color rgba="0.91764705882352937127 0.91764705882352937127 0.91764705882352937127 1.0"/>
</material>
</visual>
<!-- Shapes for ll_faa -->
<collision>
<origin xyz="1.090794121694216301e-14 -0.020903831303002662345 0.0068277128563508579506" rpy="-3.141592653589793116 -1.3962636194521678146 1.570796326794896558" />
<geometry>
<box size="0.16000000000000000333 0.055000000000000000278 0.055000000000000000278" />
</geometry>
</collision>
<inertial>
<origin xyz="4.1000001099744665112e-07 -0.018269831303003081224 0.0057673728563508927514" rpy="0 0 0"/>
<mass value="0.46714990999999950194" />
<inertia ixx="0.0010106720086173624686" ixy="-6.4114680174817274738e-09"  ixz="-1.541352073187449103e-08" iyy="0.00089215895795440058359" iyz="-0.00017524898475440695185" izz="0.00035477869622917298457" />
</inertial>
</link>

<link name="LL_FOOT">
<inertial>
<origin xyz="0 0 0" rpy="0 0 0" />
<mass value="1e-9" />
<inertia ixx="0" ixy="0" ixz="0" iyy="0" iyz="0" izz="0" />
</inertial>
</link>
<joint name="LL_FOOT_frame" type="fixed">
<origin xyz="5.0760714742636992014e-08 -0.048285133326044671342 0.011820623986993364363" rpy="3.1415926535897846783 -1.3962634015954633604 1.570796326794896558" />
<parent link="ll_faa" />
<child link="LL_FOOT" />
<axis xyz="0 0 0"/>
</joint>

<joint name="LL_FAA" type="revolute">
<origin xyz="7.771561172376095783e-16 0.019999999999998924888 1.0824674490095276269e-15" rpy="-1.5707963267948970021 -1.570796326794876574 0" />
<parent link="ll_ffe" />
<child link="ll_faa" />
<axis xyz="0 0 1"/>
<limit effort="18" velocity="42" lower="-0.52359877559829881566" upper="0.52359877559829881566"/>
<joint_properties friction="0.0"/>
</joint>

<joint name="LL_FFE" type="revolute">
<origin xyz="-0.18000000000000221378 4.0657234523511220914e-13 -4.3853809472693683347e-15" rpy="4.1335758622659789005e-30 1.5777218104420236108e-30 -6.383782391594657996e-15" />
<parent link="ll_kfe" />
<child link="ll_ffe" />
<axis xyz="0 0 1"/>
<limit effort="60" velocity="20" lower="-0.52359877559829881566" upper="1.2217304763960306069"/>
<joint_properties friction="0.0"/>
</joint>

<joint name="LL_KFE" type="revolute">
<origin xyz="-0.22000000000000022315 5.0043823252021724102e-13 0.074199999999999863287" rpy="-3.3760985920712169733e-14 7.3374569801132745765e-15 6.4670491184412426029e-15" />
<parent link="ll_hfe" />
<child link="ll_kfe" />
<axis xyz="0 0 1"/>
<limit effort="120" velocity="14" lower="0" upper="2.0943951023931952626"/>
<joint_properties friction="0.0"/>
</joint>

<joint name="LL_HFE" type="revolute">
<origin xyz="-8.3266726846886740532e-17 0.015799999999994970845 -0.064999999999999710787" rpy="-1.5707963267948823471 -0.78539816339744961127 3.2543908859931252475e-15" />
<parent link="ll_haa" />
<child link="ll_hfe" />
<axis xyz="0 0 1"/>
<limit effort="90" velocity="20" lower="-1.9198621771937625091" upper="1.9198621771937625091"/>
<joint_properties friction="0.0"/>
</joint>

<joint name="LL_HAA" type="revolute">
<origin xyz="0.015799999999996330868 -3.1918911957973250537e-16 -0.064999999999999613642" rpy="-2.9816562105458668087e-15 -1.5707963267948934494 0" />
<parent link="ll_hr" />
<child link="ll_haa" />
<axis xyz="0 0 1"/>
<limit effort="60" velocity="23" lower="-0.52359877559829881566" upper="0.785398163397448279"/>
<joint_properties friction="0.0"/>
</joint>

<joint name="LL_HR" type="revolute">
<origin xyz="-1.6653345369377348106e-16 0.069999999999999854006 -4.8572257327350598644e-17" rpy="6.776315175848504861e-28 0.78539816339744950024 4.7915784122997950057e-28" />
<parent link="torso" />
<child link="ll_hr" />
<axis xyz="0 0 1"/>
<limit effort="60" velocity="23" lower="-0.52359877559829881566" upper="1.0471975511965976313"/>
<joint_properties friction="0.0"/>
</joint>

<link name="lr_hr">
<visual>
<origin xyz="9.8130778667824987513e-17 0.070000000000000062172 1.7663540160183554957e-16" rpy="-1.802877771831609774e-27 -0.7853981633974492782 -3.4457100799534119709e-32" />
<geometry>
<mesh filename="package://cal_hum_description/meshs/lr_hr.stl"/>
</geometry>
<material name="lr_hr_material">
<color rgba="0.91764705882352937127 0.91764705882352937127 0.91764705882352937127 1.0"/>
</material>
</visual>
<!-- Shapes for lr_hr -->
<inertial>
<origin xyz="-0.005487855728788923991 -0.00079000000000022108093 -0.060008616985396355525" rpy="0 0 0"/>
<mass value="0.75099999999999023093" />
<inertia ixx="0.0015417037063559439584" ixy="1.5993778177555942461e-06"  ixz="-9.5391365132100155349e-05" iyy="0.0011651757733619498483" iyz="-5.0338451249867923064e-06" izz="0.00073817604325181066308" />
</inertial>
</link>

<link name="lr_haa">
<visual>
<origin xyz="0.064999999999999599765 0.070000000000000173195 0.015799999999996462707" rpy="3.3658857083033384115e-15 0.78539816339744850104 -9.8012208447829625117e-32" />
<geometry>
<mesh filename="package://cal_hum_description/meshs/lr_haa.stl"/>
</geometry>
<material name="lr_haa_material">
<color rgba="0.91764705882352937127 0.91764705882352937127 0.91764705882352937127 1.0"/>
</material>
</visual>
<!-- Shapes for lr_haa -->
<inertial>
<origin xyz="-0.00068406107216664735482 0.0075435900000006160179 -0.039387584164473549153" rpy="0 0 0"/>
<mass value="0.79600000000000059597" />
<inertia ixx="0.0013149682383798645853" ixy="2.9837001318818977382e-06"  ixz="5.3421388465633753245e-07" iyy="0.0016788957877882117447" iyz="9.3293013223220806686e-05" izz="0.00082881130154303808786" />
</inertial>
</link>

<link name="lr_hfe">
<visual>
<origin xyz="0.10309616869699547714 -0.011172287142743415542 0.085800000000000278821" rpy="1.5707963267948978903 2.4663018163742555816e-15 1.570796326794896558" />
<geometry>
<mesh filename="package://cal_hum_description/meshs/lr_hfe.stl"/>
</geometry>
<material name="lr_hfe_material">
<color rgba="0.91764705882352937127 0.91764705882352937127 0.91764705882352937127 1.0"/>
</material>
</visual>
<!-- Shapes for lr_hfe -->
<collision>
<origin xyz="9.6168696995316271803e-05 -2.8714274375937764994e-07 -0.054199999999999623479" rpy="-3.1415926535897922278 2.4663018163742555816e-15 1.570796326794896558" />
<geometry>
<cylinder length="0.089999999999999996669" radius="0.061499999999999999112" />
</geometry>
</collision>
<collision>
<origin xyz="-0.11490383130300468872 -2.8714274377152071427e-07 -0.059199999999999461386" rpy="-3.1415926535897922278 2.4663018163742555816e-15 1.570796326794896558" />
<geometry>
<cylinder length="0.080000000000000001665" radius="0.051999999999999997613" />
</geometry>
</collision>
<inertial>
<origin xyz="-0.054818641303004719822 0.00091571285725625985175 -0.043015999999999540715" rpy="0 0 0"/>
<mass value="2.2540000000000004476" />
<inertia ixx="0.0050840797274041525655" ixy="0.00017690116972244256761"  ixz="-0.0012741797571625503895" iyy="0.015265420753516207794" iyz="2.4300467122352837138e-05" izz="0.015856484644831022462" />
</inertial>
</link>

<link name="lr_kfe">
<visual>
<origin xyz="0.32309616869699464559 -0.011172287142751121183 0.16000000000000003109" rpy="1.570796326794896558 -1.5407439555035949432e-31 1.570796326794896558" />
<geometry>
<mesh filename="package://cal_hum_description/meshs/lr_kfe.stl"/>
</geometry>
<material name="lr_kfe_material">
<color rgba="0.91764705882352937127 0.91764705882352937127 0.91764705882352937127 1.0"/>
</material>
</visual>
<!-- Shapes for lr_kfe -->
<collision>
<origin xyz="-0.056903831303005358855 -0.0011722871427511209752 2.7755575615628913511e-17" rpy="1.570796326794896558 -1.5407439555035949432e-31 1.570796326794896558" />
<geometry>
<box size="0.02999999999999999889 0.040000000000000000833 0.16000000000000000333" />
</geometry>
</collision>
<inertial>
<origin xyz="-0.073422831303005253734 -0.0013121671427511244403 0.00043913999999997677115" rpy="0 0 0"/>
<mass value="0.24100000000000007527" />
<inertia ixx="5.8566224651899907977e-05" ixy="-6.8667149871729865835e-05"  ixz="1.0787864326449584821e-06" iyy="0.0010619126261204850283" iyz="-2.5038354916531007914e-07" izz="0.0010651730211028022192" />
</inertial>
</link>

<link name="lr_ffe">
<visual>
<origin xyz="0.50309616869699469444 -0.01117228714275079679 0.15999999999999989231" rpy="1.570796326794896558 2.9659321143084292065e-32 1.570796326794896558" />
<geometry>
<mesh filename="package://cal_hum_description/meshs/lr_ffe.stl"/>
</geometry>
<material name="lr_ffe_material">
<color rgba="0.91764705882352937127 0.91764705882352937127 0.91764705882352937127 1.0"/>
</material>
</visual>
<!-- Shapes for lr_ffe -->
<inertial>
<origin xyz="-0.0010781713030052486602 0.023770712857249198108 -6.8000000000123517196e-05" rpy="0 0 0"/>
<mass value="0.099322280000000026656" />
<inertia ixx="7.6973158492811576993e-05" ixy="-1.2302114426540098645e-05"  ixz="-2.7941566375700741419e-07" iyy="1.1391027650605248245e-05" iyz="-9.2660656262607554181e-07" izz="8.2546877026924600192e-05" />
</inertial>
</link>

<link name="lr_faa">
<visual>
<origin xyz="0.16000000000000005884 0.50309616869699469444 -0.031172287142751095579" rpy="-1.570796326794896558 -1.570796326794896558 0" />
<geometry>
<mesh filename="package://cal_hum_description/meshs/lr_faa.stl"/>
</geometry>
<material name="lr_faa_material">
<color rgba="0.91764705882352937127 0.91764705882352937127 0.91764705882352937127 1.0"/>
</material>
</visual>
<!-- Shapes for lr_faa -->
<collision>
<origin xyz="5.5511151231257827021e-17 -0.020903831303005437903 0.0068277128572489034775" rpy="-3.141592653589793116 -1.3962636194521678146 1.570796326794896558" />
<geometry>
<box size="0.16000000000000000333 0.055000000000000000278 0.055000000000000000278" />
</geometry>
</collision>
<inertial>
<origin xyz="-9.9031684314132562008e-06 -0.018269831303005634737 0.0057673728572489452171" rpy="0 0 0"/>
<mass value="0.46714990999999983501" />
<inertia ixx="0.001010612200036978877" ixy="1.5888284625438848315e-07"  ixz="1.7657167031368668287e-07" iyy="0.00089205563938504392994" iyz="-0.00017513094115976772665" izz="0.00035461577572044872394" />
</inertial>
</link>

<link name="LR_FOOT">
<inertial>
<origin xyz="0 0 0" rpy="0 0 0" />
<mass value="1e-9" />
<inertia ixx="0" ixy="0" ixz="0" iyy="0" iyz="0" izz="0" />
</inertial>
</link>
<joint name="LR_FOOT_frame" type="fixed">
<origin xyz="5.0760711967079430451e-08 -0.048285133326045004409 0.011820623986989381438" rpy="3.141592653589793116 -1.3962634015954633604 1.570796326794896558" />
<parent link="lr_faa" />
<child link="LR_FOOT" />
<axis xyz="0 0 0"/>
</joint>

<joint name="LR_FAA" type="revolute">
<origin xyz="-4.5519144009631418157e-15 0.020000000000000892064 -3.1641356201816961402e-15" rpy="-1.570796326794896558 -1.5707963267948958919 0" />
<parent link="lr_ffe" />
<child link="lr_faa" />
<axis xyz="0 0 1"/>
<limit effort="18" velocity="42" lower="-0.52359877559829881566" upper="0.52359877559829881566"/>
<joint_properties friction="0.0"/>
</joint>

<joint name="LR_FFE" type="revolute">
<origin xyz="-0.18000000000000015987 -3.2439329000766292666e-16 1.6653345369377348106e-16" rpy="2.8414770536498554039e-15 2.1649348980189791287e-15 1.9428902930938756399e-15" />
<parent link="lr_kfe" />
<child link="lr_ffe" />
<axis xyz="0 0 1"/>
<limit effort="60" velocity="23" lower="-0.52359877559829881566" upper="1.2217304763960306069"/>
<joint_properties friction="0.0"/>
</joint>

<joint name="LR_KFE" type="revolute">
<origin xyz="-0.21999999999999927947 7.3118594512422419029e-15 -0.074199999999999377565" rpy="-5.5888040731323801616e-15 -1.6961427793646633868e-16 -4.357625371653309492e-15" />
<parent link="lr_hfe" />
<child link="lr_kfe" />
<axis xyz="0 0 1"/>
<limit effort="120" velocity="14" lower="0" upper="2.0943951023931952626"/>
<joint_properties friction="0.0"/>
</joint>

<joint name="LR_HFE" type="revolute">
<origin xyz="-1.8873791418627661187e-15 -0.015799999999999994604 -0.064999999999998808731" rpy="-1.5707963267948912289 -0.78539816339743961926 -3.2139718585574148952e-15" />
<parent link="lr_haa" />
<child link="lr_hfe" />
<axis xyz="0 0 1"/>
<limit effort="90" velocity="20" lower="-1.9198621771937625091" upper="1.9198621771937625091"/>
<joint_properties friction="0.0"/>
</joint>

<joint name="LR_HAA" type="revolute">
<origin xyz="0.01579999999999619556 1.193489751472043281e-15 -0.064999999999998087086" rpy="-1.6145151215107273488e-15 -1.5707963267948941155 0" />
<parent link="lr_hr" />
<child link="lr_haa" />
<axis xyz="0 0 1"/>
<limit effort="60" velocity="23" lower="-1.0471975511965976313" upper="0.52359877559829881566"/>
<joint_properties friction="0.0"/>
</joint>

<joint name="LR_HR" type="revolute">
<origin xyz="-1.9428902930940239457e-16 -0.070000000000000062172 -5.5511151231257808532e-17" rpy="-6.2032260096825242622e-16 0.7853981633974492782 -8.7726863533765840477e-16" />
<parent link="torso" />
<child link="lr_hr" />
<axis xyz="0 0 1"/>
<limit effort="60" velocity="23" lower="-1.0471975511965976313" upper="0.52359877559829881566"/>
<joint_properties friction="0.0"/>
</joint>

<gazebo reference="ll_faa">
    <mu1>0.7</mu1>
    <mu2>0.7</mu2>
    <self_collide>0</self_collide>
    <material>Gazebo/DarkGrey</material>
    <kp value="1000000.0"/>
    <kd value="100.0"/>
</gazebo>

<gazebo reference="lr_faa">
<mu1>0.7</mu1>
<mu2>0.7</mu2>
<self_collide>0</self_collide>
<material>Gazebo/DarkGrey</material>
<kp value="1000000.0"/>
<kd value="100.0"/>
</gazebo>

<!-- ros_control plugin -->
<gazebo>
<plugin name="gazebo_ros_control" filename="liblegged_hw_sim.so">
    <robotNamespace>/</robotNamespace>
    <robotParam>legged_robot_description</robotParam>
    <robotSimType>legged_gazebo/LeggedHWSim</robotSimType>
</plugin>
</gazebo>

<gazebo>
<plugin name="p3d_base_controller" filename="libgazebo_ros_p3d.so">
    <alwaysOn>true</alwaysOn>
    <updateRate>1000.0</updateRate>
    <bodyName>torso</bodyName>
    <topicName>ground_truth/state</topicName>
    <gaussianNoise>0</gaussianNoise>
    <frameName>world</frameName>
    <xyzOffsets>0 0 0</xyzOffsets>
    <rpyOffsets>0 0 0</rpyOffsets>
</plugin>
</gazebo>

<transmission name="LL_HR_tran">
<type>transmission_interface/SimpleTransmission</type>
<joint name="LL_HR">
    <hardwareInterface>hardware_interface/EffortJointInterface</hardwareInterface>
</joint>
<actuator name="LL_HR_motor">
    <hardwareInterface>hardware_interface/EffortJointInterface</hardwareInterface>
</actuator>
</transmission>

<transmission name="LL_HAA_tran">
<type>transmission_interface/SimpleTransmission</type>
<joint name="LL_HAA">
    <hardwareInterface>hardware_interface/EffortJointInterface</hardwareInterface>
</joint>
<actuator name="LL_HAA_motor">
    <hardwareInterface>hardware_interface/EffortJointInterface</hardwareInterface>
</actuator>
</transmission>

<transmission name="LL_HFE_tran">
<type>transmission_interface/SimpleTransmission</type>
<joint name="LL_HFE">
    <hardwareInterface>hardware_interface/EffortJointInterface</hardwareInterface>
</joint>
<actuator name="LL_HFE_motor">
    <hardwareInterface>hardware_interface/EffortJointInterface</hardwareInterface>
</actuator>
</transmission>

<transmission name="LL_KFE_tran">
<type>transmission_interface/SimpleTransmission</type>
<joint name="LL_KFE">
    <hardwareInterface>hardware_interface/EffortJointInterface</hardwareInterface>
</joint>
<actuator name="LL_KFE_motor">
    <hardwareInterface>hardware_interface/EffortJointInterface</hardwareInterface>
</actuator>
</transmission>

<transmission name="LL_FFE_tran">
<type>transmission_interface/SimpleTransmission</type>
<joint name="LL_FFE">
    <hardwareInterface>hardware_interface/EffortJointInterface</hardwareInterface>
</joint>
<actuator name="LL_FFE_motor">
    <hardwareInterface>hardware_interface/EffortJointInterface</hardwareInterface>
</actuator>
</transmission>

<transmission name="LL_FAA_tran">
<type>transmission_interface/SimpleTransmission</type>
<joint name="LL_FAA">
    <hardwareInterface>hardware_interface/EffortJointInterface</hardwareInterface>
</joint>
<actuator name="LL_FAA_motor">
    <hardwareInterface>hardware_interface/EffortJointInterface</hardwareInterface>
</actuator>
</transmission>

<transmission name="LR_HR_tran">
<type>transmission_interface/SimpleTransmission</type>
<joint name="LR_HR">
    <hardwareInterface>hardware_interface/EffortJointInterface</hardwareInterface>
</joint>
<actuator name="LR_HR_motor">
    <hardwareInterface>hardware_interface/EffortJointInterface</hardwareInterface>
</actuator>
</transmission>

<transmission name="LR_HAA_tran">
<type>transmission_interface/SimpleTransmission</type>
<joint name="LR_HAA">
    <hardwareInterface>hardware_interface/EffortJointInterface</hardwareInterface>
</joint>
<actuator name="LR_HAA_motor">
    <hardwareInterface>hardware_interface/EffortJointInterface</hardwareInterface>
</actuator>
</transmission>

<transmission name="LR_HFE_tran">
<type>transmission_interface/SimpleTransmission</type>
<joint name="LR_HFE">
    <hardwareInterface>hardware_interface/EffortJointInterface</hardwareInterface>
</joint>
<actuator name="LR_HFE_motor">
    <hardwareInterface>hardware_interface/EffortJointInterface</hardwareInterface>
</actuator>
</transmission>

<transmission name="LR_KFE_tran">
<type>transmission_interface/SimpleTransmission</type>
<joint name="LR_KFE">
    <hardwareInterface>hardware_interface/EffortJointInterface</hardwareInterface>
</joint>
<actuator name="LR_KFE_motor">
    <hardwareInterface>hardware_interface/EffortJointInterface</hardwareInterface>
</actuator>
</transmission>

<transmission name="LR_FFE_tran">
<type>transmission_interface/SimpleTransmission</type>
<joint name="LR_FFE">
    <hardwareInterface>hardware_interface/EffortJointInterface</hardwareInterface>
</joint>
<actuator name="LR_FFE_motor">
    <hardwareInterface>hardware_interface/EffortJointInterface</hardwareInterface>
</actuator>
</transmission>

<transmission name="LR_FAA_tran">
<type>transmission_interface/SimpleTransmission</type>
<joint name="LR_FAA">
    <hardwareInterface>hardware_interface/EffortJointInterface</hardwareInterface>
</joint>
<actuator name="LR_FAA_motor">
    <hardwareInterface>hardware_interface/EffortJointInterface</hardwareInterface>
</actuator>
</transmission>

</robot>
