<robot name="onshape">
<link name="torso">
<visual>
<origin xyz="0 0 0" rpy="0 -0 0" />
<geometry>
<mesh filename="package://cal_hum_description/meshs/torso.stl"/>
</geometry>
<material name="torso_material">
<color rgba="0.91764705882352937127 0.91764705882352937127 0.91764705882352937127 1.0"/>
</material>
</visual>
<!-- Shapes for torso -->
<collision>
<origin xyz="0.020000000000000000416 0 0.11999999999999999556" rpy="0 -0 0" />
<geometry>
<box size="0.17999999999999999334 0.25 0.25" />
</geometry>
</collision>
<inertial>
<origin xyz="0.012329400000000019857 -0.0023557000000000048387 0.11404699999999985682" rpy="0 0 0"/>
<mass value="5.3781180999999937953" />
<inertia ixx="0.1063393572477290272" ixy="-0.0011518417369268867199"  ixz="-0.0019798987901618412405" iyy="0.077153530025598299202" iyz="0.00063966268739630647699" izz="0.049558109407867603768" />
</inertial>
</link>

<link name="ll_hr">
<visual>
<origin xyz="8.2399365108898336985e-17 -0.069999999999999840128 1.5221116882866402504e-16" rpy="1.784478888649690797e-18 -0.78539816339744950024 4.5831631551321408901e-18" />
<geometry>
<mesh filename="package://cal_hum_description/meshs/ll_hr.stl"/>
</geometry>
<material name="ll_hr_material">
<color rgba="0.91764705882352937127 0.91764705882352937127 0.91764705882352937127 1.0"/>
</material>
</visual>
<!-- Shapes for ll_hr -->
<inertial>
<origin xyz="-0.0054878557287887114874 0.00067000000000162762692 -0.060008616985397514321" rpy="0 0 0"/>
<mass value="0.75099999999998401368" />
<inertia ixx="0.001541185385699113744" ixy="3.445800320105947729e-06"  ixz="-9.5391365132054090309e-05" iyy="0.0011651757733619708818" iyz="5.6603649620036318695e-06" izz="0.00073765772259487137792" />
</inertial>
</link>

<link name="ll_haa">
<visual>
<origin xyz="0.064999999999999585887 -0.069999999999999756861 0.015799999999995963107" rpy="4.2244620531162376715e-15 0.78539816339744816798 -3.5939954818811980799e-17" />
<geometry>
<mesh filename="package://cal_hum_description/meshs/ll_haa.stl"/>
</geometry>
<material name="ll_haa_material">
<color rgba="0.91764705882352937127 0.91764705882352937127 0.91764705882352937127 1.0"/>
</material>
</visual>
<!-- Shapes for ll_haa -->
<inertial>
<origin xyz="0.00063772656283822559686 -0.0081199999999999345618 -0.060865931429811101494" rpy="0 0 0"/>
<mass value="0.85100000000001196909" />
<inertia ixx="0.0013734389493930446949" ixy="-1.9074937059429686229e-06"  ixz="4.7795124019204979432e-06" iyy="0.0017643939390453050077" iyz="-0.00013437288005948745001" izz="0.00089199996414278859194" />
</inertial>
</link>

<link name="ll_hfe">
<visual>
<origin xyz="0.10309616869699469999 -0.011172287142746005484 -0.085799999999994921995" rpy="1.5707963267949036634 1.7482394490373858198e-14 1.570796326794896558" />
<geometry>
<mesh filename="package://cal_hum_description/meshs/ll_hfe.stl"/>
</geometry>
<material name="ll_hfe_material">
<color rgba="0.91764705882352937127 0.91764705882352937127 0.91764705882352937127 1.0"/>
</material>
</visual>
<!-- Shapes for ll_hfe -->
<collision>
<origin xyz="9.6168696995704849861e-05 -2.8714274356161917368e-07 0.054200000000005646439" rpy="-3.1415926535897860106 1.7482394490373858198e-14 1.570796326794896558" />
<geometry>
<cylinder length="0.089999999999999996669" radius="0.061499999999999999112" />
</geometry>
</collision>
<collision>
<origin xyz="-0.11490383130300427239 -2.871427434800871703e-07 0.059200000000006428036" rpy="-3.1415926535897860106 1.7482394490373858198e-14 1.570796326794896558" />
<geometry>
<cylinder length="0.080000000000000001665" radius="0.051999999999999997613" />
</geometry>
</collision>
<inertial>
<origin xyz="-0.054802291303004471712 -0.00042046714274375333875 0.04301560000000613504" rpy="0 0 0"/>
<mass value="2.2535340099999987551" />
<inertia ixx="0.0050853613820006299609" ixy="0.00017735960141768852567"  ixz="0.0012738415098089519474" iyy="0.015264146154526632079" iyz="-4.5383172503089262196e-05" izz="0.01585741252279511404" />
</inertial>
</link>

<link name="ll_kfe">
<visual>
<origin xyz="0.3230961686969961999 -0.011172287143240700047 -0.15999999999999259259" rpy="1.5707963267948958919 -1.8222382377379934641e-14 1.570796326794896558" />
<geometry>
<mesh filename="package://cal_hum_description/meshs/ll_kfe.stl"/>
</geometry>
<material name="ll_kfe_material">
<color rgba="0.91764705882352937127 0.91764705882352937127 0.91764705882352937127 1.0"/>
</material>
</visual>
<!-- Shapes for ll_kfe -->
<collision>
<origin xyz="-0.056903831303003915565 -0.0011722871432436263173 7.2997163869104042533e-15" rpy="1.5707963267948958919 -1.8222382377379934641e-14 1.570796326794896558" />
<geometry>
<box size="0.02999999999999999889 0.040000000000000000833 0.16000000000000000333" />
</geometry>
</collision>
<inertial>
<origin xyz="-0.073422831303004032488 -0.0013121671432436143867 -0.00043913999999266041226" rpy="0 0 0"/>
<mass value="0.24071601000000042436" />
<inertia ixx="5.8497212291950355097e-05" ixy="-6.8586225347447689555e-05"  ixz="-1.0773459750966253426e-06" iyy="0.0010606612937310415119" iyz="2.5009653117043108784e-07" izz="0.0010639178434183466093" />
</inertial>
</link>

<link name="ll_ffe">
<visual>
<origin xyz="0.50309616869699835817 -0.011172287143647291474 -0.1599999999999881517" rpy="1.5707963267948958919 -1.8206329779458071689e-14 1.570796326794896558" />
<geometry>
<mesh filename="package://cal_hum_description/meshs/ll_ffe.stl"/>
</geometry>
<material name="ll_ffe_material">
<color rgba="0.91764705882352937127 0.91764705882352937127 0.91764705882352937127 1.0"/>
</material>
</visual>
<!-- Shapes for ll_ffe -->
<inertial>
<origin xyz="-0.0010781713030019179911 0.023770712856349816844 6.800000001212131199e-05" rpy="0 0 0"/>
<mass value="0.099322750000000015191" />
<inertia ixx="7.6973129115221454065e-05" ixy="-1.230239598872653531e-05"  ixz="2.7947672524257725611e-07" iyy="1.139116531171098203e-05" iyz="9.267040241029627232e-07" izz="8.2547053941301628448e-05" />
</inertial>
</link>

<link name="ll_faa">
<visual>
<origin xyz="-0.15999999999998909539 0.50309616869699746999 -0.031172287143649141106" rpy="-1.570796326794896558 -1.570796326794896558 0" />
<geometry>
<mesh filename="package://cal_hum_description/meshs/ll_faa.stl"/>
</geometry>
<material name="ll_faa_material">
<color rgba="0.91764705882352937127 0.91764705882352937127 0.91764705882352937127 1.0"/>
</material>
</visual>
<!-- Shapes for ll_faa -->
<collision>
<origin xyz="1.090794121694216301e-14 -0.020903831303002551323 0.0068277128563508510117" rpy="-3.141592653589793116 -1.3962636194521678146 1.570796326794896558" />
<geometry>
<box size="0.16000000000000000333 0.055000000000000000278 0.055000000000000000278" />
</geometry>
</collision>
<inertial>
<origin xyz="4.1000001083091319742e-07 -0.01826983130300241509 0.005767372856350851118" rpy="0 0 0"/>
<mass value="0.46714990999999994603" />
<inertia ixx="0.0010106720086173624686" ixy="-6.4114680174805594947e-09"  ixz="-1.5413520731867403746e-08" iyy="0.00089215895795440069201" iyz="-0.00017524898475440695185" izz="0.00035477869622917309299" />
</inertial>
</link>

<link name="LL_FOOT">
<inertial>
<origin xyz="0 0 0" rpy="0 0 0" />
<mass value="1e-9" />
<inertia ixx="0" ixy="0" ixz="0" iyy="0" iyz="0" izz="0" />
</inertial>
</link>
<joint name="LL_FOOT_frame" type="fixed">
<origin xyz="5.0760714645492477359e-08 -0.048285133326044726854 0.01182062398699337824" rpy="3.1415926535897913396 -1.3962634015954631383 1.570796326794896558" />
<parent link="ll_faa" />
<child link="LL_FOOT" />
<axis xyz="0 0 0"/>
</joint>

<joint name="LL_FAA" type="revolute">
<origin xyz="8.8817841970012523234e-16 0.019999999999998921418 1.0269562977782697999e-15" rpy="-1.5707963267947515629 -1.4450247660621533541 -1.1629114424755023013e-13" />
<parent link="ll_ffe" />
<child link="ll_faa" />
<axis xyz="0 0 1"/>
<limit effort="18" velocity="42" lower="-0.52359877559829881566" upper="0.52359877559829881566"/>
<joint_properties friction="0.0"/>
</joint>

<joint name="LL_FFE" type="revolute">
<origin xyz="-0.18000000000000204725 4.0648040489088543836e-13 -4.4131365228849972482e-15" rpy="-4.9741081456802783629e-15 -7.8078125061771119145e-15 -0.3496172140838589848" />
<parent link="ll_kfe" />
<child link="ll_ffe" />
<axis xyz="0 0 1"/>
<limit effort="60" velocity="20" lower="-0.52359877559829881566" upper="1.2217304763960306069"/>
<joint_properties friction="0.0"/>
</joint>

<joint name="LL_KFE" type="revolute">
<origin xyz="-0.2200000000000001954 5.0049547839492447565e-13 0.074199999999999807776" rpy="-1.1996374222978450601e-14 3.4286500686111271094e-14 0.98360185480604667152" />
<parent link="ll_hfe" />
<child link="ll_kfe" />
<axis xyz="0 0 1"/>
<limit effort="120" velocity="14" lower="0" upper="2.0943951023931952626"/>
<joint_properties friction="0.0"/>
</joint>

<joint name="LL_HFE" type="revolute">
<origin xyz="1.1102230246251565404e-16 0.015799999999995040234 -0.064999999999999308331" rpy="-1.5707963267948641395 -1.2485808691306654605 -4.5486223788766130327e-14" />
<parent link="ll_haa" />
<child link="ll_hfe" />
<axis xyz="0 0 1"/>
<limit effort="90" velocity="20" lower="-1.9198621771937625091" upper="1.9198621771937625091"/>
<joint_properties friction="0.0"/>
</joint>

<joint name="LL_HAA" type="revolute">
<origin xyz="0.015799999999996344746 -3.7470027081099033239e-16 -0.064999999999999613642" rpy="-1.5707963267949045516 -1.4678600129856298473 1.570796326794289488" />
<parent link="ll_hr" />
<child link="ll_haa" />
<axis xyz="0 0 1"/>
<limit effort="60" velocity="23" lower="-0.52359877559829881566" upper="0.785398163397448279"/>
<joint_properties friction="0.0"/>
</joint>

<joint name="LL_HR" type="revolute">
<origin xyz="-1.6696713456276768284e-16 0.069999999999999909517 -4.8572257327350598644e-17" rpy="-0.072206686120917601412 0.78278216060187066905 -0.10220480535128237398" />
<parent link="torso" />
<child link="ll_hr" />
<axis xyz="0 0 1"/>
<limit effort="60" velocity="23" lower="-0.52359877559829881566" upper="1.0471975511965976313"/>
<joint_properties friction="0.0"/>
</joint>

<link name="lr_hr">
<visual>
<origin xyz="9.8011876392689600834e-17 0.070000000000000062172 1.7646156474613585967e-16" rpy="-1.8059117281169420597e-18 -0.78539816339744938922 -1.4586268424080465518e-17" />
<geometry>
<mesh filename="package://cal_hum_description/meshs/lr_hr.stl"/>
</geometry>
<material name="lr_hr_material">
<color rgba="0.91764705882352937127 0.91764705882352937127 0.91764705882352937127 1.0"/>
</material>
</visual>
<!-- Shapes for lr_hr -->
<inertial>
<origin xyz="-0.0054878557287889343994 -0.00079000000000041493628 -0.060008616985396528998" rpy="0 0 0"/>
<mass value="0.75099999999998801048" />
<inertia ixx="0.0015417037063559443921" ixy="1.5993778177554881552e-06"  ixz="-9.5391365132100141796e-05" iyy="0.0011651757733619496314" iyz="-5.0338451249869210554e-06" izz="0.00073817604325181153044" />
</inertial>
</link>

<link name="lr_haa">
<visual>
<origin xyz="0.064999999999999599765 0.070000000000000173195 0.015799999999996455768" rpy="3.3645052808535628614e-15 0.78539816339744839002 -1.8995106989125444178e-17" />
<geometry>
<mesh filename="package://cal_hum_description/meshs/lr_haa.stl"/>
</geometry>
<material name="lr_haa_material">
<color rgba="0.91764705882352937127 0.91764705882352937127 0.91764705882352937127 1.0"/>
</material>
</visual>
<!-- Shapes for lr_haa -->
<inertial>
<origin xyz="-0.00068406107216634204349 0.007543590000000894441 -0.039387584164473292414" rpy="0 0 0"/>
<mass value="0.79600000000000414868" />
<inertia ixx="0.0013149682383798639348" ixy="2.9837001318819121377e-06"  ixz="5.3421388465654124387e-07" iyy="0.0016788957877882110942" iyz="9.3293013223220833791e-05" izz="0.00082881130154303808786" />
</inertial>
</link>

<link name="lr_hfe">
<visual>
<origin xyz="0.10309616869699546327 -0.011172287142743417276 0.085800000000000264944" rpy="1.5707963267948978903 2.4562794719138943382e-15 1.57079632679489678" />
<geometry>
<mesh filename="package://cal_hum_description/meshs/lr_hfe.stl"/>
</geometry>
<material name="lr_hfe_material">
<color rgba="0.91764705882352937127 0.91764705882352937127 0.91764705882352937127 1.0"/>
</material>
</visual>
<!-- Shapes for lr_hfe -->
<collision>
<origin xyz="9.6168696995302394015e-05 -2.8714274375937764994e-07 -0.054199999999999609601" rpy="-3.1415926535897917837 2.4562794719138943382e-15 1.57079632679489678" />
<geometry>
<cylinder length="0.089999999999999996669" radius="0.061499999999999999112" />
</geometry>
</collision>
<collision>
<origin xyz="-0.1149038313030047026 -2.8714274376805126732e-07 -0.059199999999999447509" rpy="-3.1415926535897917837 2.4562794719138943382e-15 1.57079632679489678" />
<geometry>
<cylinder length="0.080000000000000001665" radius="0.051999999999999997613" />
</geometry>
</collision>
<inertial>
<origin xyz="-0.054818641303004650434 0.00091571285725625822544 -0.043015999999999499082" rpy="0 0 0"/>
<mass value="2.2540000000000013358" />
<inertia ixx="0.0050840797274041516982" ixy="0.00017690116972244151051"  ixz="-0.0012741797571625516905" iyy="0.015265420753516214733" iyz="2.4300467122353365686e-05" izz="0.015856484644831015524" />
</inertial>
</link>

<link name="lr_kfe">
<visual>
<origin xyz="0.32309616869699464559 -0.011172287142751119449 0.1600000000000000866" rpy="1.570796326794896558 -4.8237997775034754387e-18 1.570796326794896558" />
<geometry>
<mesh filename="package://cal_hum_description/meshs/lr_kfe.stl"/>
</geometry>
<material name="lr_kfe_material">
<color rgba="0.91764705882352937127 0.91764705882352937127 0.91764705882352937127 1.0"/>
</material>
</visual>
<!-- Shapes for lr_kfe -->
<collision>
<origin xyz="-0.056903831303005358855 -0.0011722871427511522002 8.3266726846886740532e-17" rpy="1.570796326794896558 -4.8237997775034754387e-18 1.570796326794896558" />
<geometry>
<box size="0.02999999999999999889 0.040000000000000000833 0.16000000000000000333" />
</geometry>
</collision>
<inertial>
<origin xyz="-0.0734228313030055868 -0.0013121671427511489433 0.00043913999999989404652" rpy="0 0 0"/>
<mass value="0.24099999999999988098" />
<inertia ixx="5.8566224651899880871e-05" ixy="-6.8667149871729770967e-05"  ixz="1.0787864326449741522e-06" iyy="0.001061912626120485462" iyz="-2.5038354916530144999e-07" izz="0.0010651730211028024361" />
</inertial>
</link>

<link name="lr_ffe">
<visual>
<origin xyz="0.50309616869699469444 -0.011172287142750786382 0.1599999999999998368" rpy="1.570796326794896558 -6.8338110975211049878e-18 1.570796326794896558" />
<geometry>
<mesh filename="package://cal_hum_description/meshs/lr_ffe.stl"/>
</geometry>
<material name="lr_ffe_material">
<color rgba="0.91764705882352937127 0.91764705882352937127 0.91764705882352937127 1.0"/>
</material>
</visual>
<!-- Shapes for lr_ffe -->
<inertial>
<origin xyz="-0.0010781713030052486602 0.023770712857249205047 -6.8000000000169107898e-05" rpy="0 0 0"/>
<mass value="0.099322280000000026656" />
<inertia ixx="7.6973158492811590546e-05" ixy="-1.2302114426540091869e-05"  ixz="-2.7941566375700280845e-07" iyy="1.1391027650605246551e-05" iyz="-9.2660656262601402604e-07" izz="8.2546877026924613745e-05" />
</inertial>
</link>

<link name="lr_faa">
<visual>
<origin xyz="0.16000000000000005884 0.50309616869699458341 -0.031172287142751081701" rpy="-1.570796326794896558 -1.570796326794896558 0" />
<geometry>
<mesh filename="package://cal_hum_description/meshs/lr_faa.stl"/>
</geometry>
<material name="lr_faa_material">
<color rgba="0.91764705882352937127 0.91764705882352937127 0.91764705882352937127 1.0"/>
</material>
</visual>
<!-- Shapes for lr_faa -->
<collision>
<origin xyz="5.5511151231257827021e-17 -0.020903831303005437903 0.0068277128572489104164" rpy="-3.141592653589793116 -1.3962636194521678146 1.570796326794896558" />
<geometry>
<box size="0.16000000000000000333 0.055000000000000000278 0.055000000000000000278" />
</geometry>
</collision>
<inertial>
<origin xyz="-9.9031684313022338984e-06 -0.018269831303005190648 0.0057673728572489244004" rpy="0 0 0"/>
<mass value="0.46714991000000016808" />
<inertia ixx="0.0010106122000369801781" ixy="1.588828462543849362e-07"  ixz="1.765716703136846447e-07" iyy="0.00089205563938504403836" iyz="-0.00017513094115976813323" izz="0.00035461577572045007919" />
</inertial>
</link>

<link name="LR_FOOT">
<inertial>
<origin xyz="0 0 0" rpy="0 0 0" />
<mass value="1e-9" />
<inertia ixx="0" ixy="0" ixz="0" iyy="0" iyz="0" izz="0" />
</inertial>
</link>
<joint name="LR_FOOT_frame" type="fixed">
<origin xyz="5.0760711800545976757e-08 -0.048285133326043450097 0.011820623986989048371" rpy="-3.141592653589793116 -1.3962634015954631383 1.570796326794896558" />
<parent link="lr_faa" />
<child link="LR_FOOT" />
<axis xyz="0 0 0"/>
</joint>

<joint name="LR_FAA" type="revolute">
<origin xyz="1.6653345369377348106e-16 0.020000000000000323075 -1.9428902930940239457e-16" rpy="1.5707963267948852337 -1.4450247661876081118 -3.1415926535897811256" />
<parent link="lr_ffe" />
<child link="lr_faa" />
<axis xyz="0 0 1"/>
<limit effort="18" velocity="42" lower="-0.52359877559829881566" upper="0.52359877559829881566"/>
<joint_properties friction="0.0"/>
</joint>

<joint name="LR_FFE" type="revolute">
<origin xyz="-0.18000000000000068723 -1.6653345369377348106e-16 8.3266726846886740532e-17" rpy="1.1209570441384864999e-15 1.4760710728832299551e-15 -0.34961721405632484316" />
<parent link="lr_kfe" />
<child link="lr_ffe" />
<axis xyz="0 0 1"/>
<limit effort="60" velocity="23" lower="-0.52359877559829881566" upper="1.2217304763960306069"/>
<joint_properties friction="0.0"/>
</joint>

<joint name="LR_KFE" type="revolute">
<origin xyz="-0.21999999999999936273 7.403799795469012679e-15 -0.074199999999999266542" rpy="-2.4715536250851352852e-15 3.1294003481309170141e-15 0.9836018547500596787" />
<parent link="lr_hfe" />
<child link="lr_kfe" />
<axis xyz="0 0 1"/>
<limit effort="120" velocity="14" lower="0" upper="2.0943951023931952626"/>
<joint_properties friction="0.0"/>
</joint>

<joint name="LR_HFE" type="revolute">
<origin xyz="-1.2836953722228372499e-15 -0.015800000000000161138 -0.064999999999999391598" rpy="-1.5707963267948925612 -1.2485808690947428623 -6.3154349151414743693e-15" />
<parent link="lr_haa" />
<child link="lr_hfe" />
<axis xyz="0 0 1"/>
<limit effort="90" velocity="20" lower="-1.9198621771937625091" upper="1.9198621771937625091"/>
<joint_properties friction="0.0"/>
</joint>

<joint name="LR_HAA" type="revolute">
<origin xyz="0.015799999999996486993 -2.7755575615628913511e-16 -0.064999999999999238942" rpy="1.5707963267948976682 -1.4678600130881280794 -1.5707963267948414909" />
<parent link="lr_hr" />
<child link="lr_haa" />
<axis xyz="0 0 1"/>
<limit effort="60" velocity="23" lower="-1.0471975511965976313" upper="0.52359877559829881566"/>
<joint_properties friction="0.0"/>
</joint>

<joint name="LR_HR" type="revolute">
<origin xyz="-1.9472271017839659635e-16 -0.070000000000000103806 -5.290906601729261638e-17" rpy="0.07220668604874565244 0.78278216060711247604 0.10220480524894931529" />
<parent link="torso" />
<child link="lr_hr" />
<axis xyz="0 0 1"/>
<limit effort="60" velocity="23" lower="-1.0471975511965976313" upper="0.52359877559829881566"/>
<joint_properties friction="0.0"/>
</joint>

<gazebo reference="ll_faa">
    <mu1>0.7</mu1>
    <mu2>0.7</mu2>
    <self_collide>0</self_collide>
    <material>Gazebo/DarkGrey</material>
    <kp value="1000000.0"/>
    <kd value="100.0"/>
</gazebo>

<gazebo reference="lr_faa">
<mu1>0.7</mu1>
<mu2>0.7</mu2>
<self_collide>0</self_collide>
<material>Gazebo/DarkGrey</material>
<kp value="1000000.0"/>
<kd value="100.0"/>
</gazebo>

<!-- ros_control plugin -->
<gazebo>
<plugin name="gazebo_ros_control" filename="liblegged_hw_sim.so">
    <robotNamespace>/</robotNamespace>
    <robotParam>legged_robot_description</robotParam>
    <robotSimType>legged_gazebo/LeggedHWSim</robotSimType>
</plugin>
</gazebo>

<gazebo>
<plugin name="p3d_base_controller" filename="libgazebo_ros_p3d.so">
    <alwaysOn>true</alwaysOn>
    <updateRate>1000.0</updateRate>
    <bodyName>torso</bodyName>
    <topicName>ground_truth/state</topicName>
    <gaussianNoise>0</gaussianNoise>
    <frameName>world</frameName>
    <xyzOffsets>0 0 0</xyzOffsets>
    <rpyOffsets>0 0 0</rpyOffsets>
</plugin>
</gazebo>

<transmission name="LL_HR_tran">
<type>transmission_interface/SimpleTransmission</type>
<joint name="LL_HR">
    <hardwareInterface>hardware_interface/EffortJointInterface</hardwareInterface>
</joint>
<actuator name="LL_HR_motor">
    <hardwareInterface>hardware_interface/EffortJointInterface</hardwareInterface>
</actuator>
</transmission>

<transmission name="LL_HAA_tran">
<type>transmission_interface/SimpleTransmission</type>
<joint name="LL_HAA">
    <hardwareInterface>hardware_interface/EffortJointInterface</hardwareInterface>
</joint>
<actuator name="LL_HAA_motor">
    <hardwareInterface>hardware_interface/EffortJointInterface</hardwareInterface>
</actuator>
</transmission>

<transmission name="LL_HFE_tran">
<type>transmission_interface/SimpleTransmission</type>
<joint name="LL_HFE">
    <hardwareInterface>hardware_interface/EffortJointInterface</hardwareInterface>
</joint>
<actuator name="LL_HFE_motor">
    <hardwareInterface>hardware_interface/EffortJointInterface</hardwareInterface>
</actuator>
</transmission>

<transmission name="LL_KFE_tran">
<type>transmission_interface/SimpleTransmission</type>
<joint name="LL_KFE">
    <hardwareInterface>hardware_interface/EffortJointInterface</hardwareInterface>
</joint>
<actuator name="LL_KFE_motor">
    <hardwareInterface>hardware_interface/EffortJointInterface</hardwareInterface>
</actuator>
</transmission>

<transmission name="LL_FFE_tran">
<type>transmission_interface/SimpleTransmission</type>
<joint name="LL_FFE">
    <hardwareInterface>hardware_interface/EffortJointInterface</hardwareInterface>
</joint>
<actuator name="LL_FFE_motor">
    <hardwareInterface>hardware_interface/EffortJointInterface</hardwareInterface>
</actuator>
</transmission>

<transmission name="LL_FAA_tran">
<type>transmission_interface/SimpleTransmission</type>
<joint name="LL_FAA">
    <hardwareInterface>hardware_interface/EffortJointInterface</hardwareInterface>
</joint>
<actuator name="LL_FAA_motor">
    <hardwareInterface>hardware_interface/EffortJointInterface</hardwareInterface>
</actuator>
</transmission>

<transmission name="LR_HR_tran">
<type>transmission_interface/SimpleTransmission</type>
<joint name="LR_HR">
    <hardwareInterface>hardware_interface/EffortJointInterface</hardwareInterface>
</joint>
<actuator name="LR_HR_motor">
    <hardwareInterface>hardware_interface/EffortJointInterface</hardwareInterface>
</actuator>
</transmission>

<transmission name="LR_HAA_tran">
<type>transmission_interface/SimpleTransmission</type>
<joint name="LR_HAA">
    <hardwareInterface>hardware_interface/EffortJointInterface</hardwareInterface>
</joint>
<actuator name="LR_HAA_motor">
    <hardwareInterface>hardware_interface/EffortJointInterface</hardwareInterface>
</actuator>
</transmission>

<transmission name="LR_HFE_tran">
<type>transmission_interface/SimpleTransmission</type>
<joint name="LR_HFE">
    <hardwareInterface>hardware_interface/EffortJointInterface</hardwareInterface>
</joint>
<actuator name="LR_HFE_motor">
    <hardwareInterface>hardware_interface/EffortJointInterface</hardwareInterface>
</actuator>
</transmission>

<transmission name="LR_KFE_tran">
<type>transmission_interface/SimpleTransmission</type>
<joint name="LR_KFE">
    <hardwareInterface>hardware_interface/EffortJointInterface</hardwareInterface>
</joint>
<actuator name="LR_KFE_motor">
    <hardwareInterface>hardware_interface/EffortJointInterface</hardwareInterface>
</actuator>
</transmission>

<transmission name="LR_FFE_tran">
<type>transmission_interface/SimpleTransmission</type>
<joint name="LR_FFE">
    <hardwareInterface>hardware_interface/EffortJointInterface</hardwareInterface>
</joint>
<actuator name="LR_FFE_motor">
    <hardwareInterface>hardware_interface/EffortJointInterface</hardwareInterface>
</actuator>
</transmission>

<transmission name="LR_FAA_tran">
<type>transmission_interface/SimpleTransmission</type>
<joint name="LR_FAA">
    <hardwareInterface>hardware_interface/EffortJointInterface</hardwareInterface>
</joint>
<actuator name="LR_FAA_motor">
    <hardwareInterface>hardware_interface/EffortJointInterface</hardwareInterface>
</actuator>
</transmission>

</robot>
