<robot name="onshape">
<link name="torso">
<visual>
<origin xyz="0 0 0" rpy="0 -0 0" />
<geometry>
<mesh filename="package://cal_hum_description/meshs/torso_visual.stl"/>
</geometry>
<material name="torso_material">
<color rgba="0.91764705882352937127 0.91764705882352937127 0.91764705882352937127 1.0"/>
</material>
</visual>
<collision>
<origin xyz="0 0 0" rpy="0 -0 0" />
<geometry>
<mesh filename="package://cal_hum_description/meshs/torso_collision.stl"/>
</geometry>
</collision>
<inertial>
<origin xyz="-0.0047277400000000019756 -0.0001455300000000001601 0.10283863000000027788" rpy="0 0 0"/>
<mass value="2.9270371599999722712" />
<inertia ixx="0.0514210702318330104" ixy="-0.00058153531110748601322"  ixz="-0.0015361604440174271655" iyy="0.037409694290920399162" iyz="0.00070497665986465310635" izz="0.028925496243936584667" />
</inertial>
</link>

<link name="ll_hr">
<visual>
<origin xyz="0 0 0" rpy="0 -0 0" />
<geometry>
<mesh filename="package://cal_hum_description/meshs/ll_hr_visual.stl"/>
</geometry>
<material name="ll_hr_material">
<color rgba="0.9176470588235294823 0.9176470588235294823 0.9176470588235294823 1.0"/>
</material>
</visual>
<collision>
<origin xyz="0 0 0" rpy="0 -0 0" />
<geometry>
<mesh filename="package://cal_hum_description/meshs/ll_hr_collision.stl"/>
</geometry>
</collision>
<inertial>
<origin xyz="-0.006233895809347424731 0.00070432000000007766172 -0.037208835638444633098" rpy="0 0 0"/>
<mass value="0.73133287000000002376" />
<inertia ixx="0.0016295722474070192722" ixy="-3.587491485631832841e-05"  ixz="-8.2585115000000254961e-05" iyy="0.0015558630100000001711" iyz="6.2591175029895149975e-06" izz="0.00073101174259298064891" />
</inertial>
</link>

<link name="ll_haa">
<visual>
<origin xyz="0 0 0" rpy="0 -0 0" />
<geometry>
<mesh filename="package://cal_hum_description/meshs/ll_haa_visual.stl"/>
</geometry>
<material name="ll_haa_material">
<color rgba="0.91764705882352926025 0.91764705882352926025 0.91764705882352926025 1.0"/>
</material>
</visual>
<collision>
<origin xyz="0 0 0" rpy="0 -0 0" />
<geometry>
<mesh filename="package://cal_hum_description/meshs/ll_haa_collision.stl"/>
</geometry>
</collision>
<inertial>
<origin xyz="0.0016821232786486675029 -0.014174999999998563749 -0.038079415406075262096" rpy="0 0 0"/>
<mass value="0.79600000000000037392" />
<inertia ixx="0.0013606266472201596074" ixy="5.2319821399483149588e-06"  ixz="-2.4349982350893982649e-05" iyy="0.0017341651457972642042" iyz="-4.6775551431596259068e-05" izz="0.00080476822545456330651" />
</inertial>
</link>

<link name="ll_hfe">
<visual>
<origin xyz="0 0 0" rpy="0 -0 0" />
<geometry>
<mesh filename="package://cal_hum_description/meshs/ll_hfe_visual.stl"/>
</geometry>
<material name="ll_hfe_material">
<color rgba="0.91764705882352937127 0.91764705882352937127 0.91764705882352937127 1.0"/>
</material>
</visual>
<collision>
<origin xyz="0 0 0" rpy="0 -0 0" />
<geometry>
<mesh filename="package://cal_hum_description/meshs/ll_hfe_collision.stl"/>
</geometry>
</collision>
<inertial>
<origin xyz="-0.03366870130300374242 0.018560382857254517641 0.0094327400000052095963" rpy="0 0 0"/>
<mass value="3.5233394799999993019" />
<inertia ixx="0.01472386780775755688" ixy="-0.0011043766273472594396"  ixz="0.0050843212469392556549" iyy="0.031285359683627861349" iyz="0.0025289857534554773498" izz="0.02764146804704123786" />
</inertial>
</link>

<link name="ll_kfe">
<visual>
<origin xyz="0 0 0" rpy="0 -0 0" />
<geometry>
<mesh filename="package://cal_hum_description/meshs/ll_kfe_visual.stl"/>
</geometry>
<material name="ll_kfe_material">
<color rgba="0.91764705882352937127 0.91764705882352937127 0.91764705882352937127 1.0"/>
</material>
</visual>
<collision>
<origin xyz="0 0 0" rpy="0 -0 0" />
<geometry>
<mesh filename="package://cal_hum_description/meshs/ll_kfe_collision.stl"/>
</geometry>
</collision>
<inertial>
<origin xyz="-0.031901741303003494643 0.091689672857244858273 -0.053605439999995986577" rpy="0 0 0"/>
<mass value="0.24071601000000017456" />
<inertia ixx="0.0028203399079755608891" ixy="-0.0010287616507221770956"  ixz="0.00054797909062976723343" iyy="0.0021837337502509318946" iyz="0.0011903958858475701191" izz="0.0035876999592870844127" />
</inertial>
</link>

<link name="ll_ffe">
<visual>
<origin xyz="0 0 0" rpy="0 -0 0" />
<geometry>
<mesh filename="package://cal_hum_description/meshs/ll_ffe_visual.stl"/>
</geometry>
<material name="ll_ffe_material">
<color rgba="0.91764705882352937127 0.91764705882352937127 0.91764705882352937127 1.0"/>
</material>
</visual>
<collision>
<origin xyz="0 0 0" rpy="0 -0 0" />
<geometry>
<mesh filename="package://cal_hum_description/meshs/ll_ffe_collision.stl"/>
</geometry>
</collision>
<inertial>
<origin xyz="0.055405788696998685416 0.06331380285723732515 -0.069452679999992356086" rpy="0 0 0"/>
<mass value="0.099322750000000029069" />
<inertia ixx="0.00088993358176636509511" ixy="-0.00036825176555067606942"  ixz="0.00040621351190161245678" iyy="0.00083481807900864530431" iyz="0.00042897209409484596786" izz="0.00075505166816962972394" />
</inertial>
</link>

<link name="ll_faa">
<visual>
<origin xyz="0 0 0" rpy="0 -0 0" />
<geometry>
<mesh filename="package://cal_hum_description/meshs/ll_faa_visual.stl"/>
</geometry>
<material name="ll_faa_material">
<color rgba="0.91764705882352937127 0.91764705882352937127 0.91764705882352937127 1.0"/>
</material>
</visual>
<collision>
<origin xyz="0 0 0" rpy="0 -0 0" />
<geometry>
<mesh filename="package://cal_hum_description/meshs/ll_faa_collision.stl"/>
</geometry>
</collision>
<inertial>
<origin xyz="-0.069331049999991067878 0.052652478696997129237 0.052034212857210326852" rpy="0 0 0"/>
<mass value="0.19869954999999994705" />
<inertia ixx="0.0015737795764003577586" ixy="0.00099441722230272228122"  ixz="0.00051970219197393352755" iyy="0.0014921720313034879564" iyz="-0.00053920924933122506631" izz="0.0020995076431026024437" />
</inertial>
</link>

<link name="LL_FOOT">
<inertial>
<origin xyz="0 0 0" rpy="0 0 0" />
<mass value="1e-9" />
<inertia ixx="0" ixy="0" ixz="0" iyy="0" iyz="0" izz="0" />
</inertial>
</link>
<joint name="LL_FOOT_frame" type="fixed">
<origin xyz="1.3877787807814456755e-15 -0.033000000000000473399 0.020976404179762334068" rpy="-1.570796326794896558 -1.570796326794896558 0" />
<parent link="ll_faa" />
<child link="LL_FOOT" />
<axis xyz="0 0 0"/>
</joint>

<joint name="LL_FAA" type="revolute">
<origin xyz="1.1102230246251565404e-15 0.020000000000026586788 -1.9428902930940239457e-15" rpy="-1.5707963267948912289 -1.5707963267948901187 0" />
<parent link="ll_ffe" />
<child link="ll_faa" />
<axis xyz="0 0 1"/>
<limit effort="18" velocity="42" lower="-0.52359877559829881566" upper="0.52359877559829881566"/>
<joint_properties friction="0.0"/>
</joint>

<joint name="LL_FFE" type="revolute">
<origin xyz="-0.18000000000000215827 1.0633854907737827489e-14 -4.4964032497318839887e-15" rpy="7.3118594512411069293e-16 -3.8857805861880691907e-15 -2.4841240175987530493e-15" />
<parent link="ll_kfe" />
<child link="ll_ffe" />
<axis xyz="0 0 1"/>
<limit effort="60" velocity="20" lower="-0.52359877559829881566" upper="1.2217304763960306069"/>
<joint_properties friction="0.0"/>
</joint>

<joint name="LL_KFE" type="revolute">
<origin xyz="-0.22000000000000025091 9.5826124812958823895e-15 0.074199999999999988187" rpy="1.004141528052162953e-27 -1.9324819522386478582e-15 0" />
<parent link="ll_hfe" />
<child link="ll_kfe" />
<axis xyz="0 0 1"/>
<limit effort="120" velocity="14" lower="0" upper="2.0943951023931952626"/>
<joint_properties friction="0.0"/>
</joint>

<joint name="LL_HFE" type="revolute">
<origin xyz="-1.7763568394002504647e-15 0.015799999999995956168 -0.065000000000000793254" rpy="-1.5707963267948983344 -0.78539816339744794593 -8.4801163929695123491e-15" />
<parent link="ll_haa" />
<child link="ll_hfe" />
<axis xyz="0 0 1"/>
<limit effort="90" velocity="20" lower="-1.9198621771937625091" upper="1.9198621771937625091"/>
<joint_properties friction="0.0"/>
</joint>

<joint name="LL_HAA" type="revolute">
<origin xyz="0.015799999999996143518 -1.360023205165816762e-15 -0.064999999999997906674" rpy="1.300043474638154911e-15 -1.5707963267948870101 0" />
<parent link="ll_hr" />
<child link="ll_haa" />
<axis xyz="0 0 1"/>
<limit effort="60" velocity="23" lower="-0.52359877559829881566" upper="0.785398163397448279"/>
<joint_properties friction="0.0"/>
</joint>

<joint name="LL_HR" type="revolute">
<origin xyz="-1.5249813257468713577e-16 0.069999999999999895639 -4.8559453586656778667e-17" rpy="-5.5967126325698482102e-15 0.78539816339745760487 -7.914946909686092054e-15" />
<parent link="torso" />
<child link="ll_hr" />
<axis xyz="0 0 1"/>
<limit effort="60" velocity="23" lower="-0.52359877559829881566" upper="1.0471975511965976313"/>
<joint_properties friction="0.0"/>
</joint>

<link name="lr_hr">
<visual>
<origin xyz="0 0 0" rpy="0 -0 0" />
<geometry>
<mesh filename="package://cal_hum_description/meshs/lr_hr_visual.stl"/>
</geometry>
<material name="lr_hr_material">
<color rgba="0.91764705882352937127 0.91764705882352937127 0.91764705882352937127 1.0"/>
</material>
</visual>
<collision>
<origin xyz="0 0 0" rpy="0 -0 0" />
<geometry>
<mesh filename="package://cal_hum_description/meshs/lr_hr_collision.stl"/>
</geometry>
</collision>
<inertial>
<origin xyz="-0.006272744255905754289 -7.2999999999656672856e-05 -0.037208665932817054645" rpy="0 0 0"/>
<mass value="0.73133287000000202216" />
<inertia ixx="0.0015767504898084260499" ixy="2.9236526815963415181e-06"  ixz="-7.7950030122177536114e-05" iyy="0.0011872135223235460739" iyz="5.8143685298789138402e-06" izz="0.0006729301636178837507" />
</inertial>
</link>

<link name="lr_haa">
<visual>
<origin xyz="0 0 0" rpy="0 -0 0" />
<geometry>
<mesh filename="package://cal_hum_description/meshs/lr_haa_visual.stl"/>
</geometry>
<material name="lr_haa_material">
<color rgba="0.91764705882352937127 0.91764705882352937127 0.91764705882352937127 1.0"/>
</material>
</visual>
<collision>
<origin xyz="0 0 0" rpy="0 -0 0" />
<geometry>
<mesh filename="package://cal_hum_description/meshs/lr_haa_collision.stl"/>
</geometry>
</collision>
<inertial>
<origin xyz="-0.00068406107216702194667 0.0075435900000006914784 -0.039387584164473465886" rpy="0 0 0"/>
<mass value="0.79599999999999981881" />
<inertia ixx="0.0013145690070147913325" ixy="1.2277307941681377517e-06"  ixz="1.0572493149092354145e-06" iyy="0.0017084353807578758679" iyz="0.00011067577011200063872" izz="0.00078005700465820645376" />
</inertial>
</link>

<link name="lr_hfe">
<visual>
<origin xyz="0 0 0" rpy="0 -0 0" />
<geometry>
<mesh filename="package://cal_hum_description/meshs/lr_hfe_visual.stl"/>
</geometry>
<material name="lr_hfe_material">
<color rgba="0.91764705882352937127 0.91764705882352937127 0.91764705882352937127 1.0"/>
</material>
</visual>
<collision>
<origin xyz="0 0 0" rpy="0 -0 0" />
<geometry>
<mesh filename="package://cal_hum_description/meshs/lr_hfe_collision.stl"/>
</geometry>
</collision>
<inertial>
<origin xyz="-0.053342251303004573071 0.00067071285726267096394 -0.040248999999999104937" rpy="0 0 0"/>
<mass value="2.4960000000000079901" />
<inertia ixx="0.0057303405152839669706" ixy="0.00018071400178366854106"  ixz="-0.0014540430701991120636" iyy="0.017093925036772650294" iyz="2.7180240668987892794e-05" izz="0.017600457476287231784" />
</inertial>
</link>

<link name="lr_kfe">
<visual>
<origin xyz="0 0 0" rpy="0 -0 0" />
<geometry>
<mesh filename="package://cal_hum_description/meshs/lr_kfe_visual.stl"/>
</geometry>
<material name="lr_kfe_material">
<color rgba="0.91764705882352937127 0.91764705882352937127 0.91764705882352937127 1.0"/>
</material>
</visual>
<collision>
<origin xyz="0 0 0" rpy="0 -0 0" />
<geometry>
<mesh filename="package://cal_hum_description/meshs/lr_kfe_collision.stl"/>
</geometry>
</collision>
<inertial>
<origin xyz="-0.073422831303005198222 -0.0013121671427424284884 0.0004391400000001433046" rpy="0 0 0"/>
<mass value="0.24100000000000015854" />
<inertia ixx="5.8566224651896878987e-05" ixy="-6.8667149871732481472e-05"  ixz="1.0787864326451372061e-06" iyy="0.0010619126261204796073" iyz="-2.5038354916523792252e-07" izz="0.0010651730211028002677" />
</inertial>
</link>

<link name="lr_ffe">
<visual>
<origin xyz="0 0 0" rpy="0 -0 0" />
<geometry>
<mesh filename="package://cal_hum_description/meshs/lr_ffe_visual.stl"/>
</geometry>
<material name="lr_ffe_material">
<color rgba="0.91764705882352937127 0.91764705882352937127 0.91764705882352937127 1.0"/>
</material>
</visual>
<collision>
<origin xyz="0 0 0" rpy="0 -0 0" />
<geometry>
<mesh filename="package://cal_hum_description/meshs/lr_ffe_collision.stl"/>
</geometry>
</collision>
<inertial>
<origin xyz="-0.0010781713030053596825 0.02377071285725790642 -6.7999999999984739318e-05" rpy="0 0 0"/>
<mass value="0.099322280000000012778" />
<inertia ixx="7.6973158492800531683e-05" ixy="-1.2302114426539824206e-05"  ixz="-2.7941566375723076619e-07" iyy="1.1391027650605376994e-05" iyz="-9.2660656262801418847e-07" izz="8.2546877026913717513e-05" />
</inertial>
</link>

<link name="lr_faa">
<visual>
<origin xyz="0 0 0" rpy="0 -0 0" />
<geometry>
<mesh filename="package://cal_hum_description/meshs/lr_faa_visual.stl"/>
</geometry>
<material name="lr_faa_material">
<color rgba="0.91764705882352937127 0.91764705882352937127 0.91764705882352937127 1.0"/>
</material>
</visual>
<collision>
<origin xyz="0 0 0" rpy="0 -0 0" />
<geometry>
<mesh filename="package://cal_hum_description/meshs/lr_faa_collision.stl"/>
</geometry>
</collision>
<inertial>
<origin xyz="7.8300000001196856658e-05 -0.0037475313030053136742 0.012491522857246622341" rpy="0 0 0"/>
<mass value="0.19869955000000003031" />
<inertia ixx="0.00030590484912064767279" ixy="-2.2494771641131645871e-07"  ixz="1.4827443740915118375e-07" iyy="0.00025477811414993862572" iyz="7.6884878815159130873e-06" izz="0.00015851210513034478091" />
</inertial>
</link>

<link name="LR_FOOT">
<inertial>
<origin xyz="0 0 0" rpy="0 0 0" />
<mass value="1e-9" />
<inertia ixx="0" ixy="0" ixz="0" iyy="0" iyz="0" izz="0" />
</inertial>
</link>
<joint name="LR_FOOT_frame" type="fixed">
<origin xyz="-7.771561172376095783e-16 -0.032999999999999585221 0.020976404179758215834" rpy="-1.570796326794896558 -1.570796326794896558 0" />
<parent link="lr_faa" />
<child link="LR_FOOT" />
<axis xyz="0 0 0"/>
</joint>

<joint name="LR_FAA" type="revolute">
<origin xyz="-1.1102230246251565404e-16 0.020000000000011272649 -1.1102230246251565404e-15" rpy="-1.570796326794896558 -1.5707963267948952257 0" />
<parent link="lr_ffe" />
<child link="lr_faa" />
<axis xyz="0 0 1"/>
<limit effort="18" velocity="42" lower="-0.52359877559829881566" upper="0.52359877559829881566"/>
<joint_properties friction="0.0"/>
</joint>

<joint name="LR_FFE" type="revolute">
<origin xyz="-0.17999999999999954925 -2.6888213877640509963e-16 1.3877787807814456755e-16" rpy="1.3641350715342211265e-16 -1.3045120539345628793e-15 -1.1124684032044933672e-16" />
<parent link="lr_kfe" />
<child link="lr_ffe" />
<axis xyz="0 0 1"/>
<limit effort="60" velocity="23" lower="-0.52359877559829881566" upper="1.2217304763960306069"/>
<joint_properties friction="0.0"/>
</joint>

<joint name="LR_KFE" type="revolute">
<origin xyz="-0.21999999999999950151 5.2510079617817950748e-15 -0.074199999999999738387" rpy="-8.3136953572731735262e-16 -1.537353622424777934e-15 -1.6653345369376596223e-16" />
<parent link="lr_hfe" />
<child link="lr_kfe" />
<axis xyz="0 0 1"/>
<limit effort="120" velocity="14" lower="0" upper="2.0943951023931952626"/>
<joint_properties friction="0.0"/>
</joint>

<joint name="LR_HFE" type="revolute">
<origin xyz="-5.7037707890117417264e-15 -0.015799999999999800315 -0.064999999999993979261" rpy="-1.5707963267948923392 -0.78539816339744894513 -6.4495050167007133749e-15" />
<parent link="lr_haa" />
<child link="lr_hfe" />
<axis xyz="0 0 1"/>
<limit effort="90" velocity="20" lower="-1.9198621771937625091" upper="1.9198621771937625091"/>
<joint_properties friction="0.0"/>
</joint>

<joint name="LR_HAA" type="revolute">
<origin xyz="0.015799999999996518218 -3.8857805861880478915e-16 -0.064999999999998905875" rpy="-2.9423517219288057983e-15 -1.5707963267948932273 0" />
<parent link="lr_hr" />
<child link="lr_haa" />
<axis xyz="0 0 1"/>
<limit effort="60" velocity="23" lower="-1.0471975511965976313" upper="0.52359877559829881566"/>
<joint_properties friction="0.0"/>
</joint>

<joint name="LR_HR" type="revolute">
<origin xyz="-1.7663949738338549142e-16 -0.070000000000000103806 -5.9783511249299864752e-17" rpy="4.5998802503059629481e-17 0.78539816339744816798 6.5052130350937854523e-17" />
<parent link="torso" />
<child link="lr_hr" />
<axis xyz="0 0 1"/>
<limit effort="60" velocity="23" lower="-1.0471975511965976313" upper="0.52359877559829881566"/>
<joint_properties friction="0.0"/>
</joint>


</robot>
