<robot name="onshape">
<link name="torso">
<visual>
<origin xyz="0 0 0" rpy="0 -0 0" />
<geometry>
<mesh filename="package://cal_hum_description/meshs/torso.stl"/>
</geometry>
<material name="torso_material">
<color rgba="0.91764705882352937127 0.91764705882352937127 0.91764705882352937127 1.0"/>
</material>
</visual>
<!-- Shapes for torso -->
<collision>
<origin xyz="0.020000000000000000416 0 0.11999999999999999556" rpy="0 -0 0" />
<geometry>
<box size="0.17999999999999999334 0.25 0.25" />
</geometry>
</collision>
<inertial>
<origin xyz="-0.0047277399999999785568 -0.00014552999999999942826 0.10283862999999975052" rpy="0 0 0"/>
<mass value="2.9270371599999869261" />
<inertia ixx="0.051421070231833392039" ixy="-0.00058153531110747809854"  ixz="-0.0015361604440174521022" iyy="0.037409694290920697535" iyz="0.00070497665986464616746" izz="0.028925496243936813651" />
</inertial>
</link>

<link name="ll_hr">
<visual>
<origin xyz="7.3495744739961666717e-17 -0.069999999999999895639 1.4216918258373129891e-16" rpy="-9.4325346629638684967e-28 -0.78539816339744805695 -2.92963410521073999e-32" />
<geometry>
<mesh filename="package://cal_hum_description/meshs/ll_hr.stl"/>
</geometry>
<material name="ll_hr_material">
<color rgba="0.91764705882352937127 0.91764705882352937127 0.91764705882352937127 1.0"/>
</material>
</visual>
<!-- Shapes for ll_hr -->
<inertial>
<origin xyz="-0.0062338958093474160574 0.0007043200000000083812 -0.037208835638444598404" rpy="0 0 0"/>
<mass value="0.73133287000000068989" />
<inertia ixx="0.0016295722474070190554" ixy="-3.587491485631832841e-05"  ixz="-8.2585115000000214303e-05" iyy="0.0015558630100000001711" iyz="6.2591175029895166916e-06" izz="0.00073101174259298054049" />
</inertial>
</link>

<link name="ll_haa">
<visual>
<origin xyz="0.064999999999998128719 -0.069999999999998424594 0.015799999999996167804" rpy="-1.8385391135088677578e-15 0.78539816339744861207 1.1095225332913601355e-31" />
<geometry>
<mesh filename="package://cal_hum_description/meshs/ll_haa.stl"/>
</geometry>
<material name="ll_haa_material">
<color rgba="0.91764705882352937127 0.91764705882352937127 0.91764705882352937127 1.0"/>
</material>
</visual>
<!-- Shapes for ll_haa -->
<inertial>
<origin xyz="0.0016821232786487227973 -0.014174999999998626199 -0.038079415406075199646" rpy="0 0 0"/>
<mass value="0.7960000000000012621" />
<inertia ixx="0.0013606266472201613421" ixy="5.2319821399484038973e-06"  ixz="-2.4349982350893792913e-05" iyy="0.0017341651457972659389" iyz="-4.6775551431596272621e-05" izz="0.00080476822545456449913" />
</inertial>
</link>

<link name="ll_hfe">
<visual>
<origin xyz="0.10309616869699694819 -0.01117228714274486924 -0.085799999999993839528" rpy="1.5707963267948887864 -6.0836744561200820005e-15 1.570796326794896558" />
<geometry>
<mesh filename="package://cal_hum_description/meshs/ll_hfe.stl"/>
</geometry>
<material name="ll_hfe_material">
<color rgba="0.91764705882352937127 0.91764705882352937127 0.91764705882352937127 1.0"/>
</material>
</visual>
<!-- Shapes for ll_hfe -->
<inertial>
<origin xyz="-0.053342251303004031837 0.00067071285725437378156 0.040249000000005086264" rpy="0 0 0"/>
<mass value="3.5233394799999935287" />
<inertia ixx="0.0080865453048196631047" ixy="0.0002675652081535744996"  ixz="0.00204391935161887979" iyy="0.024145532511684043159" iyz="-4.7596530522284173929e-05" izz="0.024862312559039857068" />
</inertial>
</link>

<link name="ll_kfe">
<visual>
<origin xyz="0.32309616869699725461 -0.011172287142754453587 -0.15999999999999381384" rpy="1.5707963267948887864 -6.083674456119109335e-15 1.570796326794896558" />
<geometry>
<mesh filename="package://cal_hum_description/meshs/ll_kfe.stl"/>
</geometry>
<material name="ll_kfe_material">
<color rgba="0.91764705882352937127 0.91764705882352937127 0.91764705882352937127 1.0"/>
</material>
</visual>
<!-- Shapes for ll_kfe -->
<inertial>
<origin xyz="-0.073422831303004032488 -0.0013121671427554250366 -0.00043913999999683811428" rpy="0 0 0"/>
<mass value="0.24071601000000050763" />
<inertia ixx="5.8497212292252461256e-05" ixy="-6.8586225349883729206e-05"  ixz="-1.0773459750958680952e-06" iyy="0.0010606612937307338153" iyz="2.5009653116889234661e-07" izz="0.0010639178434183333821" />
</inertial>
</link>

<link name="ll_ffe">
<visual>
<origin xyz="0.50309616869699913533 -0.011172287142762124534 -0.15999999999998928968" rpy="1.5707963267948887864 -6.0836744561191101239e-15 1.570796326794896558" />
<geometry>
<mesh filename="package://cal_hum_description/meshs/ll_ffe.stl"/>
</geometry>
<material name="ll_ffe_material">
<color rgba="0.91764705882352937127 0.91764705882352937127 0.91764705882352937127 1.0"/>
</material>
</visual>
<!-- Shapes for ll_ffe -->
<inertial>
<origin xyz="-0.0010781713030021400357 0.023770712857236902388 6.800000000701108768e-05" rpy="0 0 0"/>
<mass value="0.099322750000000042947" />
<inertia ixx="7.6973129119037588214e-05" ixy="-1.2302395988913202737e-05"  ixz="2.7947672524308732876e-07" iyy="1.1391165311710926126e-05" iyz="9.2670402412126615228e-07" izz="8.2547053945117572862e-05" />
</inertial>
</link>

<link name="ll_faa">
<visual>
<origin xyz="-0.15999999999999109379 0.50309616869699724795 -0.031172287142789682768" rpy="-1.570796326794896558 -1.570796326794896558 0" />
<geometry>
<mesh filename="package://cal_hum_description/meshs/ll_faa.stl"/>
</geometry>
<material name="ll_faa_material">
<color rgba="0.91764705882352937127 0.91764705882352937127 0.91764705882352937127 1.0"/>
</material>
</visual>
<!-- Shapes for ll_faa -->
<collision>
<origin xyz="8.9095397726168812369e-15 -0.0049038313030027591566 0.019827712857210313957" rpy="-1.570796326794896558 -1.570796326794896558 0" />
<geometry>
<box size="0.14000000000000001332 0.055000000000000000278 0.055000000000000000278" />
</geometry>
</collision>
<inertial>
<origin xyz="-7.8299999991066071559e-05 -0.0037475313030027601613 0.012491522857210321518" rpy="0 0 0"/>
<mass value="0.19869954999999991929" />
<inertia ixx="0.00030582119012797018276" ixy="2.444096297002520177e-07"  ixz="-4.3047033575109327101e-08" iyy="0.00025490104976526485733" iyz="7.5828600679237334202e-06" izz="0.00015855135836541825304" />
</inertial>
</link>

<link name="LL_FOOT">
<inertial>
<origin xyz="0 0 0" rpy="0 0 0" />
<mass value="1e-9" />
<inertia ixx="0" ixy="0" ixz="0" iyy="0" iyz="0" izz="0" />
</inertial>
</link>
<joint name="LL_FOOT_frame" type="fixed">
<origin xyz="1.360023205165816762e-15 -0.033000000000000473399 0.020976404179762337537" rpy="-1.570796326794896558 -1.570796326794896558 0" />
<parent link="ll_faa" />
<child link="LL_FOOT" />
<axis xyz="0 0 0"/>
</joint>

<joint name="LL_FAA" type="revolute">
<origin xyz="-2.2204460492503130808e-16 0.020000000000026614544 -2.8588242884097780916e-15" rpy="-1.570796326794896558 -1.5707963267948870101 0" />
<parent link="ll_ffe" />
<child link="ll_faa" />
<axis xyz="0 0 1"/>
<limit effort="18" velocity="42" lower="-0.52359877559829881566" upper="0.52359877559829881566"/>
<joint_properties friction="0.0"/>
</joint>

<joint name="LL_FFE" type="revolute">
<origin xyz="-0.18000000000000104805 7.6379874647258816367e-15 -3.5527136788005009294e-15" rpy="-4.7237149809748546698e-16 1.4636729328685165243e-17 -2.1608234000908133641e-17" />
<parent link="ll_kfe" />
<child link="ll_ffe" />
<axis xyz="0 0 1"/>
<limit effort="60" velocity="20" lower="-0.52359877559829881566" upper="1.2217304763960306069"/>
<joint_properties friction="0.0"/>
</joint>

<joint name="LL_KFE" type="revolute">
<origin xyz="-0.21999999999999791944 1.0247011572594999507e-14 0.074199999999998045297" rpy="9.0122625749589332474e-16 -9.6855554553076782161e-15 -1.1275702593848007602e-15" />
<parent link="ll_hfe" />
<child link="ll_kfe" />
<axis xyz="0 0 1"/>
<limit effort="120" velocity="14" lower="0" upper="2.0943951023931952626"/>
<joint_properties friction="0.0"/>
</joint>

<joint name="LL_HFE" type="revolute">
<origin xyz="-1.7902346272080649214e-15 0.015799999999995956168 -0.065000000000000807132" rpy="-1.57079632679489678 -0.78539816339745571749 -2.5516191694803642929e-14" />
<parent link="ll_haa" />
<child link="ll_hfe" />
<axis xyz="0 0 1"/>
<limit effort="90" velocity="20" lower="-1.9198621771937625091" upper="1.9198621771937625091"/>
<joint_properties friction="0.0"/>
</joint>

<joint name="LL_HAA" type="revolute">
<origin xyz="0.01579999999999582086 -1.8596235662471372052e-15 -0.06499999999999730993" rpy="9.9396442047859508385e-16 -1.5707963267948770181 0" />
<parent link="ll_hr" />
<child link="ll_haa" />
<axis xyz="0 0 1"/>
<limit effort="60" velocity="23" lower="-0.52359877559829881566" upper="0.785398163397448279"/>
<joint_properties friction="0.0"/>
</joint>

<joint name="LL_HR" type="revolute">
<origin xyz="-1.5249813257468723438e-16 0.069999999999999895639 -4.8559453586656408888e-17" rpy="-1.1530883081439468873e-16 0.78539816339745505136 -3.9899370513288793298e-16" />
<parent link="torso" />
<child link="ll_hr" />
<axis xyz="0 0 1"/>
<limit effort="60" velocity="23" lower="-0.52359877559829881566" upper="1.0471975511965976313"/>
<joint_properties friction="0.0"/>
</joint>

<link name="lr_hr">
<visual>
<origin xyz="8.2629660217742679531e-17 0.070000000000000103806 1.6717631263260787336e-16" rpy="-1.8089567794274052882e-27 -0.78539816339744805695 -2.5195485606773874785e-32" />
<geometry>
<mesh filename="package://cal_hum_description/meshs/lr_hr.stl"/>
</geometry>
<material name="lr_hr_material">
<color rgba="0.91764705882352937127 0.91764705882352937127 0.91764705882352937127 1.0"/>
</material>
</visual>
<!-- Shapes for lr_hr -->
<inertial>
<origin xyz="-0.0062727442559057672994 -7.2999999999795450734e-05 -0.037208665932817124034" rpy="0 0 0"/>
<mass value="0.73133287000000057887" />
<inertia ixx="0.0015767504898084243152" ixy="2.92365268159633813e-06"  ixz="-7.7950030122177115985e-05" iyy="0.0011872135223235443392" iyz="5.814368529879037507e-06" izz="0.00067293016361788299175" />
</inertial>
</link>

<link name="lr_haa">
<visual>
<origin xyz="0.064999999999999238942 0.070000000000000214828 0.01579999999999669863" rpy="4.1611137104217372739e-15 0.78539816339744750184 -2.609581273203703118e-32" />
<geometry>
<mesh filename="package://cal_hum_description/meshs/lr_haa.stl"/>
</geometry>
<material name="lr_haa_material">
<color rgba="0.91764705882352937127 0.91764705882352937127 0.91764705882352937127 1.0"/>
</material>
</visual>
<!-- Shapes for lr_haa -->
<inertial>
<origin xyz="-0.00068406107216706368845 0.007543590000000649845 -0.039387584164473493642" rpy="0 0 0"/>
<mass value="0.79599999999999948574" />
<inertia ixx="0.0013145690070147908989" ixy="1.2277307941681250462e-06"  ixz="1.057249314909298942e-06" iyy="0.0017084353807578752174" iyz="0.00011067577011200051675" izz="0.00078005700465820634534" />
</inertial>
</link>

<link name="lr_hfe">
<visual>
<origin xyz="0.1030961686969951302 -0.011172287142737326662 0.085800000000000556377" rpy="1.5707963267948961139 -2.85792382801746712e-16 1.570796326794896558" />
<geometry>
<mesh filename="package://cal_hum_description/meshs/lr_hfe.stl"/>
</geometry>
<material name="lr_hfe_material">
<color rgba="0.91764705882352937127 0.91764705882352937127 0.91764705882352937127 1.0"/>
</material>
</visual>
<!-- Shapes for lr_hfe -->
<inertial>
<origin xyz="-0.05334225130300464246 0.00067071285726267443339 -0.040248999999999146571" rpy="0 0 0"/>
<mass value="2.4960000000000071019" />
<inertia ixx="0.0057303405152839669706" ixy="0.00018071400178366818869"  ixz="-0.0014540430701991109794" iyy="0.017093925036772636417" iyz="2.7180240668987892794e-05" izz="0.017600457476287214437" />
</inertial>
</link>

<link name="lr_kfe">
<visual>
<origin xyz="0.32309616869699459007 -0.011172287142742421545 0.16000000000000014211" rpy="1.570796326794896558 7.0634502777214636062e-33 1.570796326794896558" />
<geometry>
<mesh filename="package://cal_hum_description/meshs/lr_kfe.stl"/>
</geometry>
<material name="lr_kfe_material">
<color rgba="0.91764705882352937127 0.91764705882352937127 0.91764705882352937127 1.0"/>
</material>
</visual>
<!-- Shapes for lr_kfe -->
<inertial>
<origin xyz="-0.073422831303005364756 -0.0013121671427424232842 0.00043914000000006003788" rpy="0 0 0"/>
<mass value="0.24100000000000004752" />
<inertia ixx="5.8566224651896851882e-05" ixy="-6.8667149871732427262e-05"  ixz="1.078786432645136359e-06" iyy="0.0010619126261204789568" iyz="-2.5038354916523654609e-07" izz="0.0010651730211027991835" />
</inertial>
</link>

<link name="lr_ffe">
<visual>
<origin xyz="0.50309616869699469444 -0.011172287142742098887 0.16000000000000003109" rpy="1.570796326794896558 -1.5913500354879966716e-32 1.570796326794896558" />
<geometry>
<mesh filename="package://cal_hum_description/meshs/lr_ffe.stl"/>
</geometry>
<material name="lr_ffe_material">
<color rgba="0.91764705882352937127 0.91764705882352937127 0.91764705882352937127 1.0"/>
</material>
</visual>
<!-- Shapes for lr_ffe -->
<inertial>
<origin xyz="-0.0010781713030053596825 0.02377071285725790642 -6.7999999999984739318e-05" rpy="0 0 0"/>
<mass value="0.099322280000000012778" />
<inertia ixx="7.6973158492800531683e-05" ixy="-1.2302114426539829289e-05"  ixz="-2.7941566375723071325e-07" iyy="1.1391027650605378688e-05" iyz="-9.2660656262801376495e-07" izz="8.2546877026913690408e-05" />
</inertial>
</link>

<link name="lr_faa">
<visual>
<origin xyz="0.16000000000000116906 0.50309616869699480546 -0.031172287142753371536" rpy="-1.570796326794896558 -1.570796326794896558 0" />
<geometry>
<mesh filename="package://cal_hum_description/meshs/lr_faa.stl"/>
</geometry>
<material name="lr_faa_material">
<color rgba="0.91764705882352937127 0.91764705882352937127 0.91764705882352937127 1.0"/>
</material>
</visual>
<!-- Shapes for lr_faa -->
<collision>
<origin xyz="1.1657341758564143674e-15 -0.0049038313030052016472 0.019827712857246625189" rpy="-1.570796326794896558 -1.570796326794896558 0" />
<geometry>
<box size="0.14000000000000001332 0.055000000000000000278 0.055000000000000000278" />
</geometry>
</collision>
<inertial>
<origin xyz="7.8300000001169101083e-05 -0.0037475313030053136742 0.012491522857246632749" rpy="0 0 0"/>
<mass value="0.1986995499999999748" />
<inertia ixx="0.00030590484912064767279" ixy="-2.2494771641131389114e-07"  ixz="1.4827443740915031024e-07" iyy="0.00025477811414993857151" iyz="7.6884878815159080051e-06" izz="0.0001585121051303447538" />
</inertial>
</link>

<link name="LR_FOOT">
<inertial>
<origin xyz="0 0 0" rpy="0 0 0" />
<mass value="1e-9" />
<inertia ixx="0" ixy="0" ixz="0" iyy="0" iyz="0" izz="0" />
</inertial>
</link>
<joint name="LR_FOOT_frame" type="fixed">
<origin xyz="-6.9388939039072283776e-16 -0.032999999999999141131 0.020976404179758219304" rpy="-1.570796326794896558 -1.570796326794896558 0" />
<parent link="lr_faa" />
<child link="LR_FOOT" />
<axis xyz="0 0 0"/>
</joint>

<joint name="LR_FAA" type="revolute">
<origin xyz="0 0.020000000000011439183 -1.1379786002407854539e-15" rpy="-1.5707963267948961139 -1.5707963267948961139 0" />
<parent link="lr_ffe" />
<child link="lr_faa" />
<axis xyz="0 0 1"/>
<limit effort="18" velocity="42" lower="-0.52359877559829881566" upper="0.52359877559829881566"/>
<joint_properties friction="0.0"/>
</joint>

<joint name="LR_FFE" type="revolute">
<origin xyz="-0.18000000000000010436 -3.2265856653168611956e-16 1.1102230246251565404e-16" rpy="4.9088374165698854435e-16 9.020562075078750025e-16 4.9379514839931034925e-16" />
<parent link="lr_kfe" />
<child link="lr_ffe" />
<axis xyz="0 0 1"/>
<limit effort="60" velocity="23" lower="-0.52359877559829881566" upper="1.2217304763960306069"/>
<joint_properties friction="0.0"/>
</joint>

<joint name="LR_KFE" type="revolute">
<origin xyz="-0.21999999999999936273 5.1399856593192794207e-15 -0.074199999999999738387" rpy="-6.6483608203348431256e-16 -1.5373536224247538737e-15 8.165942964201880017e-31" />
<parent link="lr_hfe" />
<child link="lr_kfe" />
<axis xyz="0 0 1"/>
<limit effort="120" velocity="14" lower="0" upper="2.0943951023931952626"/>
<joint_properties friction="0.0"/>
</joint>

<joint name="LR_HFE" type="revolute">
<origin xyz="-6.8417493892525271804e-15 -0.015800000000001562794 -0.064999999999994256816" rpy="-1.570796326794891673 -0.78539816339744905616 -6.3317480822994348165e-15" />
<parent link="lr_haa" />
<child link="lr_hfe" />
<axis xyz="0 0 1"/>
<limit effort="90" velocity="20" lower="-1.9198621771937625091" upper="1.9198621771937625091"/>
<joint_properties friction="0.0"/>
</joint>

<joint name="LR_HAA" type="revolute">
<origin xyz="0.015799999999996230254 1.3461454173580023053e-15 -0.064999999999997726263" rpy="-2.5294501794417421484e-15 -1.5707963267948930053 0" />
<parent link="lr_hr" />
<child link="lr_haa" />
<axis xyz="0 0 1"/>
<limit effort="60" velocity="23" lower="-1.0471975511965976313" upper="0.52359877559829881566"/>
<joint_properties friction="0.0"/>
</joint>

<joint name="LR_HR" type="revolute">
<origin xyz="-1.7663949738338549142e-16 -0.070000000000000103806 -5.9783511249299827774e-17" rpy="-4.767057147862150383e-16 0.78539816339744816798 -6.741636871132349286e-16" />
<parent link="torso" />
<child link="lr_hr" />
<axis xyz="0 0 1"/>
<limit effort="60" velocity="23" lower="-1.0471975511965976313" upper="0.52359877559829881566"/>
<joint_properties friction="0.0"/>
</joint>

<!-- ros_control plugin -->
<gazebo>
    <plugin name="gazebo_ros_control" filename="liblegged_hw_sim.so">
        <robotNamespace>/</robotNamespace>
        <robotParam>legged_robot_description</robotParam>
        <robotSimType>legged_gazebo/LeggedHWSim</robotSimType>
    </plugin>
</gazebo>

<gazebo>
    <plugin name="p3d_base_controller" filename="libgazebo_ros_p3d.so">
        <alwaysOn>true</alwaysOn>
        <updateRate>1000.0</updateRate>
        <bodyName>torso</bodyName>
        <topicName>ground_truth/state</topicName>
        <gaussianNoise>0</gaussianNoise>
        <frameName>world</frameName>
        <xyzOffsets>0 0 0</xyzOffsets>
        <rpyOffsets>0 0 0</rpyOffsets>
    </plugin>
</gazebo>

</robot>
